2025-08-18 00:15:13 - features.naver_cafe.adapters - ERROR - Playwright 게시판 조회 실패: Page.goto: 'NoneType' object has no attribute 'send'
2025-08-18 00:17:45 - asyncio - ERROR - Task was destroyed but it is pending!
task: <Task pending name='Task-2' coro=<Connection.run() running at C:\Users\wogud\AppData\Local\Programs\Python\Python313\Lib\site-packages\playwright\_impl\_connection.py:312> wait_for=<Future pending cb=[Task.task_wakeup()]>>
2025-08-18 00:18:03 - features.naver_cafe.adapters - ERROR - Playwright 게시판 조회 실패: Page.goto: 'NoneType' object has no attribute 'send'
2025-08-18 00:19:13 - asyncio - ERROR - Task was destroyed but it is pending!
task: <Task pending name='Task-2' coro=<Connection.run() running at C:\Users\wogud\AppData\Local\Programs\Python\Python313\Lib\site-packages\playwright\_impl\_connection.py:312> wait_for=<Future pending cb=[Task.task_wakeup()]>>
2025-08-18 00:19:29 - features.naver_cafe.adapters - ERROR - Playwright 게시판 조회 실패: Page.goto: 'NoneType' object has no attribute 'send'
2025-08-18 00:20:13 - asyncio - ERROR - Task was destroyed but it is pending!
task: <Task pending name='Task-2' coro=<Connection.run() running at C:\Users\wogud\AppData\Local\Programs\Python\Python313\Lib\site-packages\playwright\_impl\_connection.py:312> wait_for=<Future pending cb=[Task.task_wakeup()]>>
2025-08-18 00:20:39 - features.naver_cafe.adapters - ERROR - Playwright 게시판 조회 실패: Page.goto: 'NoneType' object has no attribute 'send'
2025-08-18 00:21:36 - asyncio - ERROR - Task was destroyed but it is pending!
task: <Task pending name='Task-2' coro=<Connection.run() running at C:\Users\wogud\AppData\Local\Programs\Python\Python313\Lib\site-packages\playwright\_impl\_connection.py:312> wait_for=<Future pending cb=[Task.task_wakeup()]>>
2025-08-18 00:21:53 - features.naver_cafe.adapters - ERROR - Playwright 게시판 조회 실패: Page.goto: 'NoneType' object has no attribute 'send'
2025-08-18 00:23:04 - asyncio - ERROR - Task was destroyed but it is pending!
task: <Task pending name='Task-2' coro=<Connection.run() running at C:\Users\wogud\AppData\Local\Programs\Python\Python313\Lib\site-packages\playwright\_impl\_connection.py:312> wait_for=<Future pending cb=[Task.task_wakeup()]>>
2025-08-18 00:23:13 - features.naver_cafe.adapters - ERROR - === 게시판 로딩 시도 1/3 실패 ===
2025-08-18 00:23:13 - features.naver_cafe.adapters - ERROR - 에러 타입: <class 'AttributeError'>
2025-08-18 00:23:13 - features.naver_cafe.adapters - ERROR - 에러 메시지: Page.goto: 'NoneType' object has no attribute 'send'
2025-08-18 00:23:13 - features.naver_cafe.adapters - ERROR - 에러 상세: AttributeError("Page.goto: 'NoneType' object has no attribute 'send'")
2025-08-18 00:23:13 - features.naver_cafe.adapters - ERROR - 현재 self._page 상태: <Page url='https://section.cafe.naver.com/ca-fe/home/search/cafes?q=%EA%B0%95%EC%95%84%EC%A7%80&od=2'>
2025-08-18 00:23:13 - features.naver_cafe.adapters - ERROR - self._page._is_closed: N/A
2025-08-18 00:23:13 - features.naver_cafe.adapters - ERROR - 현재 browser_context 상태: <BrowserContext browser=<Browser type=<BrowserType name=chromium executable_path=C:\Users\wogud\AppData\Local\ms-playwright\chromium-1181\chrome-win\chrome.exe> version=139.0.7258.5>>
2025-08-18 00:23:13 - features.naver_cafe.adapters - ERROR - 스택 트레이스:
Traceback (most recent call last):
  File "c:\Users\wogud\OneDrive\Desktop\클로드코드\integrated_management_system\src\features\naver_cafe\adapters.py", line 320, in _get_boards_with_playwright
    await self._page.goto(cafe_info.url, wait_until='networkidle', timeout=20000)
  File "C:\Users\wogud\AppData\Local\Programs\Python\Python313\Lib\site-packages\playwright\async_api\_generated.py", line 8992, in goto
    await self._impl_obj.goto(
        url=url, timeout=timeout, waitUntil=wait_until, referer=referer
    )
  File "C:\Users\wogud\AppData\Local\Programs\Python\Python313\Lib\site-packages\playwright\_impl\_page.py", line 556, in goto
    return await self._main_frame.goto(**locals_to_params(locals()))
           ^^^^^^^^^^^^^^^^^^^^^^^^^^^^^^^^^^^^^^^^^^^^^^^^^^^^^^^^^
  File "C:\Users\wogud\AppData\Local\Programs\Python\Python313\Lib\site-packages\playwright\_impl\_frame.py", line 153, in goto
    await self._channel.send(
        "goto", self._navigation_timeout, locals_to_params(locals())
    )
  File "C:\Users\wogud\AppData\Local\Programs\Python\Python313\Lib\site-packages\playwright\_impl\_connection.py", line 69, in send
    return await self._connection.wrap_api_call(
           ^^^^^^^^^^^^^^^^^^^^^^^^^^^^^^^^^^^^^
    ...<3 lines>...
    )
    ^
  File "C:\Users\wogud\AppData\Local\Programs\Python\Python313\Lib\site-packages\playwright\_impl\_connection.py", line 558, in wrap_api_call
    raise rewrite_error(error, f"{parsed_st['apiName']}: {error}") from None
AttributeError: Page.goto: 'NoneType' object has no attribute 'send'

2025-08-18 00:23:14 - features.naver_cafe.adapters - ERROR - === 게시판 로딩 시도 2/3 실패 ===
2025-08-18 00:23:14 - features.naver_cafe.adapters - ERROR - 에러 타입: <class 'AttributeError'>
2025-08-18 00:23:14 - features.naver_cafe.adapters - ERROR - 에러 메시지: Page.goto: 'NoneType' object has no attribute 'send'
2025-08-18 00:23:14 - features.naver_cafe.adapters - ERROR - 에러 상세: AttributeError("Page.goto: 'NoneType' object has no attribute 'send'")
2025-08-18 00:23:14 - features.naver_cafe.adapters - ERROR - 현재 self._page 상태: <Page url='https://section.cafe.naver.com/ca-fe/home/search/cafes?q=%EA%B0%95%EC%95%84%EC%A7%80&od=2'>
2025-08-18 00:23:14 - features.naver_cafe.adapters - ERROR - self._page._is_closed: N/A
2025-08-18 00:23:14 - features.naver_cafe.adapters - ERROR - 현재 browser_context 상태: <BrowserContext browser=<Browser type=<BrowserType name=chromium executable_path=C:\Users\wogud\AppData\Local\ms-playwright\chromium-1181\chrome-win\chrome.exe> version=139.0.7258.5>>
2025-08-18 00:23:14 - features.naver_cafe.adapters - ERROR - 스택 트레이스:
Traceback (most recent call last):
  File "c:\Users\wogud\OneDrive\Desktop\클로드코드\integrated_management_system\src\features\naver_cafe\adapters.py", line 320, in _get_boards_with_playwright
    await self._page.goto(cafe_info.url, wait_until='networkidle', timeout=20000)
  File "C:\Users\wogud\AppData\Local\Programs\Python\Python313\Lib\site-packages\playwright\async_api\_generated.py", line 8992, in goto
    await self._impl_obj.goto(
        url=url, timeout=timeout, waitUntil=wait_until, referer=referer
    )
  File "C:\Users\wogud\AppData\Local\Programs\Python\Python313\Lib\site-packages\playwright\_impl\_page.py", line 556, in goto
    return await self._main_frame.goto(**locals_to_params(locals()))
           ^^^^^^^^^^^^^^^^^^^^^^^^^^^^^^^^^^^^^^^^^^^^^^^^^^^^^^^^^
  File "C:\Users\wogud\AppData\Local\Programs\Python\Python313\Lib\site-packages\playwright\_impl\_frame.py", line 153, in goto
    await self._channel.send(
        "goto", self._navigation_timeout, locals_to_params(locals())
    )
  File "C:\Users\wogud\AppData\Local\Programs\Python\Python313\Lib\site-packages\playwright\_impl\_connection.py", line 69, in send
    return await self._connection.wrap_api_call(
           ^^^^^^^^^^^^^^^^^^^^^^^^^^^^^^^^^^^^^
    ...<3 lines>...
    )
    ^
  File "C:\Users\wogud\AppData\Local\Programs\Python\Python313\Lib\site-packages\playwright\_impl\_connection.py", line 558, in wrap_api_call
    raise rewrite_error(error, f"{parsed_st['apiName']}: {error}") from None
AttributeError: Page.goto: 'NoneType' object has no attribute 'send'

2025-08-18 00:23:16 - features.naver_cafe.adapters - ERROR - === 게시판 로딩 시도 3/3 실패 ===
2025-08-18 00:23:16 - features.naver_cafe.adapters - ERROR - 에러 타입: <class 'AttributeError'>
2025-08-18 00:23:16 - features.naver_cafe.adapters - ERROR - 에러 메시지: Page.goto: 'NoneType' object has no attribute 'send'
2025-08-18 00:23:16 - features.naver_cafe.adapters - ERROR - 에러 상세: AttributeError("Page.goto: 'NoneType' object has no attribute 'send'")
2025-08-18 00:23:16 - features.naver_cafe.adapters - ERROR - 현재 self._page 상태: <Page url='https://section.cafe.naver.com/ca-fe/home/search/cafes?q=%EA%B0%95%EC%95%84%EC%A7%80&od=2'>
2025-08-18 00:23:16 - features.naver_cafe.adapters - ERROR - self._page._is_closed: N/A
2025-08-18 00:23:16 - features.naver_cafe.adapters - ERROR - 현재 browser_context 상태: <BrowserContext browser=<Browser type=<BrowserType name=chromium executable_path=C:\Users\wogud\AppData\Local\ms-playwright\chromium-1181\chrome-win\chrome.exe> version=139.0.7258.5>>
2025-08-18 00:23:16 - features.naver_cafe.adapters - ERROR - 스택 트레이스:
Traceback (most recent call last):
  File "c:\Users\wogud\OneDrive\Desktop\클로드코드\integrated_management_system\src\features\naver_cafe\adapters.py", line 320, in _get_boards_with_playwright
    await self._page.goto(cafe_info.url, wait_until='networkidle', timeout=20000)
  File "C:\Users\wogud\AppData\Local\Programs\Python\Python313\Lib\site-packages\playwright\async_api\_generated.py", line 8992, in goto
    await self._impl_obj.goto(
        url=url, timeout=timeout, waitUntil=wait_until, referer=referer
    )
  File "C:\Users\wogud\AppData\Local\Programs\Python\Python313\Lib\site-packages\playwright\_impl\_page.py", line 556, in goto
    return await self._main_frame.goto(**locals_to_params(locals()))
           ^^^^^^^^^^^^^^^^^^^^^^^^^^^^^^^^^^^^^^^^^^^^^^^^^^^^^^^^^
  File "C:\Users\wogud\AppData\Local\Programs\Python\Python313\Lib\site-packages\playwright\_impl\_frame.py", line 153, in goto
    await self._channel.send(
        "goto", self._navigation_timeout, locals_to_params(locals())
    )
  File "C:\Users\wogud\AppData\Local\Programs\Python\Python313\Lib\site-packages\playwright\_impl\_connection.py", line 69, in send
    return await self._connection.wrap_api_call(
           ^^^^^^^^^^^^^^^^^^^^^^^^^^^^^^^^^^^^^
    ...<3 lines>...
    )
    ^
  File "C:\Users\wogud\AppData\Local\Programs\Python\Python313\Lib\site-packages\playwright\_impl\_connection.py", line 558, in wrap_api_call
    raise rewrite_error(error, f"{parsed_st['apiName']}: {error}") from None
AttributeError: Page.goto: 'NoneType' object has no attribute 'send'

2025-08-18 00:23:16 - features.naver_cafe.adapters - ERROR - Playwright 게시판 조회 실패: Page.goto: 'NoneType' object has no attribute 'send'
2025-08-18 00:23:35 - asyncio - ERROR - Task was destroyed but it is pending!
task: <Task pending name='Task-2' coro=<Connection.run() running at C:\Users\wogud\AppData\Local\Programs\Python\Python313\Lib\site-packages\playwright\_impl\_connection.py:312> wait_for=<Future pending cb=[Task.task_wakeup()]>>
2025-08-18 00:26:11 - features.naver_cafe.adapters - ERROR - === 게시판 로딩 시도 1/3 실패 ===
2025-08-18 00:26:11 - features.naver_cafe.adapters - ERROR - 에러 타입: <class 'AttributeError'>
2025-08-18 00:26:11 - features.naver_cafe.adapters - ERROR - 에러 메시지: Page.goto: 'NoneType' object has no attribute 'send'
2025-08-18 00:26:11 - features.naver_cafe.adapters - ERROR - 에러 상세: AttributeError("Page.goto: 'NoneType' object has no attribute 'send'")
2025-08-18 00:26:11 - features.naver_cafe.adapters - ERROR - 현재 self._page 상태: <Page url='https://section.cafe.naver.com/ca-fe/home/search/cafes?q=%EA%B0%95%EC%95%84%EC%A7%80%E3%85%8F&od=2'>
2025-08-18 00:26:11 - features.naver_cafe.adapters - ERROR - self._page._is_closed: N/A
2025-08-18 00:26:11 - features.naver_cafe.adapters - ERROR - 현재 browser_context 상태: <BrowserContext browser=<Browser type=<BrowserType name=chromium executable_path=C:\Users\wogud\AppData\Local\ms-playwright\chromium-1181\chrome-win\chrome.exe> version=139.0.7258.5>>
2025-08-18 00:26:11 - features.naver_cafe.adapters - ERROR - 스택 트레이스:
Traceback (most recent call last):
  File "c:\Users\wogud\OneDrive\Desktop\클로드코드\integrated_management_system\src\features\naver_cafe\adapters.py", line 347, in _get_boards_with_playwright
    await self._page.goto(cafe_info.url, wait_until='networkidle', timeout=20000)
  File "C:\Users\wogud\AppData\Local\Programs\Python\Python313\Lib\site-packages\playwright\async_api\_generated.py", line 8992, in goto
    await self._impl_obj.goto(
        url=url, timeout=timeout, waitUntil=wait_until, referer=referer
    )
  File "C:\Users\wogud\AppData\Local\Programs\Python\Python313\Lib\site-packages\playwright\_impl\_page.py", line 556, in goto
    return await self._main_frame.goto(**locals_to_params(locals()))
           ^^^^^^^^^^^^^^^^^^^^^^^^^^^^^^^^^^^^^^^^^^^^^^^^^^^^^^^^^
  File "C:\Users\wogud\AppData\Local\Programs\Python\Python313\Lib\site-packages\playwright\_impl\_frame.py", line 153, in goto
    await self._channel.send(
        "goto", self._navigation_timeout, locals_to_params(locals())
    )
  File "C:\Users\wogud\AppData\Local\Programs\Python\Python313\Lib\site-packages\playwright\_impl\_connection.py", line 69, in send
    return await self._connection.wrap_api_call(
           ^^^^^^^^^^^^^^^^^^^^^^^^^^^^^^^^^^^^^
    ...<3 lines>...
    )
    ^
  File "C:\Users\wogud\AppData\Local\Programs\Python\Python313\Lib\site-packages\playwright\_impl\_connection.py", line 558, in wrap_api_call
    raise rewrite_error(error, f"{parsed_st['apiName']}: {error}") from None
AttributeError: Page.goto: 'NoneType' object has no attribute 'send'

2025-08-18 00:26:12 - features.naver_cafe.adapters - ERROR - === 게시판 로딩 시도 2/3 실패 ===
2025-08-18 00:26:12 - features.naver_cafe.adapters - ERROR - 에러 타입: <class 'AttributeError'>
2025-08-18 00:26:12 - features.naver_cafe.adapters - ERROR - 에러 메시지: Page.goto: 'NoneType' object has no attribute 'send'
2025-08-18 00:26:12 - features.naver_cafe.adapters - ERROR - 에러 상세: AttributeError("Page.goto: 'NoneType' object has no attribute 'send'")
2025-08-18 00:26:12 - features.naver_cafe.adapters - ERROR - 현재 self._page 상태: <Page url='https://section.cafe.naver.com/ca-fe/home/search/cafes?q=%EA%B0%95%EC%95%84%EC%A7%80%E3%85%8F&od=2'>
2025-08-18 00:26:12 - features.naver_cafe.adapters - ERROR - self._page._is_closed: N/A
2025-08-18 00:26:12 - features.naver_cafe.adapters - ERROR - 현재 browser_context 상태: <BrowserContext browser=<Browser type=<BrowserType name=chromium executable_path=C:\Users\wogud\AppData\Local\ms-playwright\chromium-1181\chrome-win\chrome.exe> version=139.0.7258.5>>
2025-08-18 00:26:12 - features.naver_cafe.adapters - ERROR - 스택 트레이스:
Traceback (most recent call last):
  File "c:\Users\wogud\OneDrive\Desktop\클로드코드\integrated_management_system\src\features\naver_cafe\adapters.py", line 347, in _get_boards_with_playwright
    await self._page.goto(cafe_info.url, wait_until='networkidle', timeout=20000)
  File "C:\Users\wogud\AppData\Local\Programs\Python\Python313\Lib\site-packages\playwright\async_api\_generated.py", line 8992, in goto
    await self._impl_obj.goto(
        url=url, timeout=timeout, waitUntil=wait_until, referer=referer
    )
  File "C:\Users\wogud\AppData\Local\Programs\Python\Python313\Lib\site-packages\playwright\_impl\_page.py", line 556, in goto
    return await self._main_frame.goto(**locals_to_params(locals()))
           ^^^^^^^^^^^^^^^^^^^^^^^^^^^^^^^^^^^^^^^^^^^^^^^^^^^^^^^^^
  File "C:\Users\wogud\AppData\Local\Programs\Python\Python313\Lib\site-packages\playwright\_impl\_frame.py", line 153, in goto
    await self._channel.send(
        "goto", self._navigation_timeout, locals_to_params(locals())
    )
  File "C:\Users\wogud\AppData\Local\Programs\Python\Python313\Lib\site-packages\playwright\_impl\_connection.py", line 69, in send
    return await self._connection.wrap_api_call(
           ^^^^^^^^^^^^^^^^^^^^^^^^^^^^^^^^^^^^^
    ...<3 lines>...
    )
    ^
  File "C:\Users\wogud\AppData\Local\Programs\Python\Python313\Lib\site-packages\playwright\_impl\_connection.py", line 558, in wrap_api_call
    raise rewrite_error(error, f"{parsed_st['apiName']}: {error}") from None
AttributeError: Page.goto: 'NoneType' object has no attribute 'send'

2025-08-18 00:26:14 - features.naver_cafe.adapters - ERROR - === 게시판 로딩 시도 3/3 실패 ===
2025-08-18 00:26:14 - features.naver_cafe.adapters - ERROR - 에러 타입: <class 'AttributeError'>
2025-08-18 00:26:14 - features.naver_cafe.adapters - ERROR - 에러 메시지: Page.goto: 'NoneType' object has no attribute 'send'
2025-08-18 00:26:14 - features.naver_cafe.adapters - ERROR - 에러 상세: AttributeError("Page.goto: 'NoneType' object has no attribute 'send'")
2025-08-18 00:26:14 - features.naver_cafe.adapters - ERROR - 현재 self._page 상태: <Page url='https://section.cafe.naver.com/ca-fe/home/search/cafes?q=%EA%B0%95%EC%95%84%EC%A7%80%E3%85%8F&od=2'>
2025-08-18 00:26:14 - features.naver_cafe.adapters - ERROR - self._page._is_closed: N/A
2025-08-18 00:26:14 - features.naver_cafe.adapters - ERROR - 현재 browser_context 상태: <BrowserContext browser=<Browser type=<BrowserType name=chromium executable_path=C:\Users\wogud\AppData\Local\ms-playwright\chromium-1181\chrome-win\chrome.exe> version=139.0.7258.5>>
2025-08-18 00:26:14 - features.naver_cafe.adapters - ERROR - 스택 트레이스:
Traceback (most recent call last):
  File "c:\Users\wogud\OneDrive\Desktop\클로드코드\integrated_management_system\src\features\naver_cafe\adapters.py", line 347, in _get_boards_with_playwright
    await self._page.goto(cafe_info.url, wait_until='networkidle', timeout=20000)
  File "C:\Users\wogud\AppData\Local\Programs\Python\Python313\Lib\site-packages\playwright\async_api\_generated.py", line 8992, in goto
    await self._impl_obj.goto(
        url=url, timeout=timeout, waitUntil=wait_until, referer=referer
    )
  File "C:\Users\wogud\AppData\Local\Programs\Python\Python313\Lib\site-packages\playwright\_impl\_page.py", line 556, in goto
    return await self._main_frame.goto(**locals_to_params(locals()))
           ^^^^^^^^^^^^^^^^^^^^^^^^^^^^^^^^^^^^^^^^^^^^^^^^^^^^^^^^^
  File "C:\Users\wogud\AppData\Local\Programs\Python\Python313\Lib\site-packages\playwright\_impl\_frame.py", line 153, in goto
    await self._channel.send(
        "goto", self._navigation_timeout, locals_to_params(locals())
    )
  File "C:\Users\wogud\AppData\Local\Programs\Python\Python313\Lib\site-packages\playwright\_impl\_connection.py", line 69, in send
    return await self._connection.wrap_api_call(
           ^^^^^^^^^^^^^^^^^^^^^^^^^^^^^^^^^^^^^
    ...<3 lines>...
    )
    ^
  File "C:\Users\wogud\AppData\Local\Programs\Python\Python313\Lib\site-packages\playwright\_impl\_connection.py", line 558, in wrap_api_call
    raise rewrite_error(error, f"{parsed_st['apiName']}: {error}") from None
AttributeError: Page.goto: 'NoneType' object has no attribute 'send'

2025-08-18 00:26:14 - features.naver_cafe.adapters - ERROR - Playwright 게시판 조회 실패: Page.goto: 'NoneType' object has no attribute 'send'
2025-08-18 00:30:29 - asyncio - ERROR - Task was destroyed but it is pending!
task: <Task pending name='Task-2' coro=<Connection.run() running at C:\Users\wogud\AppData\Local\Programs\Python\Python313\Lib\site-packages\playwright\_impl\_connection.py:312> wait_for=<Future pending cb=[Task.task_wakeup()]>>
2025-08-18 00:30:51 - features.naver_cafe.worker - ERROR - 게시판 로딩 실패: 'cp949' codec can't encode character '\u26a1' in position 0: illegal multibyte sequence
2025-08-18 00:32:14 - features.naver_cafe.service - ERROR - >>> SERVICE.PY get_boards_for_cafe 메서드 진입! <<<
2025-08-18 00:32:14 - features.naver_cafe.adapters - ERROR - !!! ADAPTERS.PY get_cafe_boards 메서드 진입! !!!
2025-08-18 00:32:14 - features.naver_cafe.adapters - ERROR - !!! _get_boards_with_playwright 메서드 시작! !!!
2025-08-18 00:32:14 - features.naver_cafe.adapters - ERROR - === 게시판 로딩 시도 1/3 실패 ===
2025-08-18 00:32:14 - features.naver_cafe.adapters - ERROR - 에러 타입: <class 'AttributeError'>
2025-08-18 00:32:14 - features.naver_cafe.adapters - ERROR - 에러 메시지: Page.goto: 'NoneType' object has no attribute 'send'
2025-08-18 00:32:14 - features.naver_cafe.adapters - ERROR - 에러 상세: AttributeError("Page.goto: 'NoneType' object has no attribute 'send'")
2025-08-18 00:32:14 - features.naver_cafe.adapters - ERROR - 현재 self._page 상태: <Page url='https://section.cafe.naver.com/ca-fe/home/search/cafes?q=%EA%B0%95%EC%95%84%EC%A7%80&od=2'>
2025-08-18 00:32:14 - features.naver_cafe.adapters - ERROR - self._page._is_closed: N/A
2025-08-18 00:32:14 - features.naver_cafe.adapters - ERROR - 현재 browser_context 상태: <BrowserContext browser=<Browser type=<BrowserType name=chromium executable_path=C:\Users\wogud\AppData\Local\ms-playwright\chromium-1181\chrome-win\chrome.exe> version=139.0.7258.5>>
2025-08-18 00:32:14 - features.naver_cafe.adapters - ERROR - 스택 트레이스:
Traceback (most recent call last):
  File "C:\Users\wogud\OneDrive\Desktop\클로드코드\integrated_management_system\src\features\naver_cafe\adapters.py", line 359, in _get_boards_with_playwright
    await self._page.goto(cafe_info.url, wait_until='networkidle', timeout=20000)
  File "C:\Users\wogud\AppData\Local\Programs\Python\Python313\Lib\site-packages\playwright\async_api\_generated.py", line 8992, in goto
    await self._impl_obj.goto(
        url=url, timeout=timeout, waitUntil=wait_until, referer=referer
    )
  File "C:\Users\wogud\AppData\Local\Programs\Python\Python313\Lib\site-packages\playwright\_impl\_page.py", line 556, in goto
    return await self._main_frame.goto(**locals_to_params(locals()))
           ^^^^^^^^^^^^^^^^^^^^^^^^^^^^^^^^^^^^^^^^^^^^^^^^^^^^^^^^^
  File "C:\Users\wogud\AppData\Local\Programs\Python\Python313\Lib\site-packages\playwright\_impl\_frame.py", line 153, in goto
    await self._channel.send(
        "goto", self._navigation_timeout, locals_to_params(locals())
    )
  File "C:\Users\wogud\AppData\Local\Programs\Python\Python313\Lib\site-packages\playwright\_impl\_connection.py", line 69, in send
    return await self._connection.wrap_api_call(
           ^^^^^^^^^^^^^^^^^^^^^^^^^^^^^^^^^^^^^
    ...<3 lines>...
    )
    ^
  File "C:\Users\wogud\AppData\Local\Programs\Python\Python313\Lib\site-packages\playwright\_impl\_connection.py", line 558, in wrap_api_call
    raise rewrite_error(error, f"{parsed_st['apiName']}: {error}") from None
AttributeError: Page.goto: 'NoneType' object has no attribute 'send'

2025-08-18 00:32:15 - features.naver_cafe.adapters - ERROR - === 게시판 로딩 시도 2/3 실패 ===
2025-08-18 00:32:15 - features.naver_cafe.adapters - ERROR - 에러 타입: <class 'AttributeError'>
2025-08-18 00:32:15 - features.naver_cafe.adapters - ERROR - 에러 메시지: Page.goto: 'NoneType' object has no attribute 'send'
2025-08-18 00:32:15 - features.naver_cafe.adapters - ERROR - 에러 상세: AttributeError("Page.goto: 'NoneType' object has no attribute 'send'")
2025-08-18 00:32:15 - features.naver_cafe.adapters - ERROR - 현재 self._page 상태: <Page url='https://section.cafe.naver.com/ca-fe/home/search/cafes?q=%EA%B0%95%EC%95%84%EC%A7%80&od=2'>
2025-08-18 00:32:15 - features.naver_cafe.adapters - ERROR - self._page._is_closed: N/A
2025-08-18 00:32:15 - features.naver_cafe.adapters - ERROR - 현재 browser_context 상태: <BrowserContext browser=<Browser type=<BrowserType name=chromium executable_path=C:\Users\wogud\AppData\Local\ms-playwright\chromium-1181\chrome-win\chrome.exe> version=139.0.7258.5>>
2025-08-18 00:32:15 - features.naver_cafe.adapters - ERROR - 스택 트레이스:
Traceback (most recent call last):
  File "C:\Users\wogud\OneDrive\Desktop\클로드코드\integrated_management_system\src\features\naver_cafe\adapters.py", line 359, in _get_boards_with_playwright
    await self._page.goto(cafe_info.url, wait_until='networkidle', timeout=20000)
  File "C:\Users\wogud\AppData\Local\Programs\Python\Python313\Lib\site-packages\playwright\async_api\_generated.py", line 8992, in goto
    await self._impl_obj.goto(
        url=url, timeout=timeout, waitUntil=wait_until, referer=referer
    )
  File "C:\Users\wogud\AppData\Local\Programs\Python\Python313\Lib\site-packages\playwright\_impl\_page.py", line 556, in goto
    return await self._main_frame.goto(**locals_to_params(locals()))
           ^^^^^^^^^^^^^^^^^^^^^^^^^^^^^^^^^^^^^^^^^^^^^^^^^^^^^^^^^
  File "C:\Users\wogud\AppData\Local\Programs\Python\Python313\Lib\site-packages\playwright\_impl\_frame.py", line 153, in goto
    await self._channel.send(
        "goto", self._navigation_timeout, locals_to_params(locals())
    )
  File "C:\Users\wogud\AppData\Local\Programs\Python\Python313\Lib\site-packages\playwright\_impl\_connection.py", line 69, in send
    return await self._connection.wrap_api_call(
           ^^^^^^^^^^^^^^^^^^^^^^^^^^^^^^^^^^^^^
    ...<3 lines>...
    )
    ^
  File "C:\Users\wogud\AppData\Local\Programs\Python\Python313\Lib\site-packages\playwright\_impl\_connection.py", line 558, in wrap_api_call
    raise rewrite_error(error, f"{parsed_st['apiName']}: {error}") from None
AttributeError: Page.goto: 'NoneType' object has no attribute 'send'

2025-08-18 00:32:17 - features.naver_cafe.adapters - ERROR - === 게시판 로딩 시도 3/3 실패 ===
2025-08-18 00:32:17 - features.naver_cafe.adapters - ERROR - 에러 타입: <class 'AttributeError'>
2025-08-18 00:32:17 - features.naver_cafe.adapters - ERROR - 에러 메시지: Page.goto: 'NoneType' object has no attribute 'send'
2025-08-18 00:32:17 - features.naver_cafe.adapters - ERROR - 에러 상세: AttributeError("Page.goto: 'NoneType' object has no attribute 'send'")
2025-08-18 00:32:17 - features.naver_cafe.adapters - ERROR - 현재 self._page 상태: <Page url='https://section.cafe.naver.com/ca-fe/home/search/cafes?q=%EA%B0%95%EC%95%84%EC%A7%80&od=2'>
2025-08-18 00:32:17 - features.naver_cafe.adapters - ERROR - self._page._is_closed: N/A
2025-08-18 00:32:17 - features.naver_cafe.adapters - ERROR - 현재 browser_context 상태: <BrowserContext browser=<Browser type=<BrowserType name=chromium executable_path=C:\Users\wogud\AppData\Local\ms-playwright\chromium-1181\chrome-win\chrome.exe> version=139.0.7258.5>>
2025-08-18 00:32:17 - features.naver_cafe.adapters - ERROR - 스택 트레이스:
Traceback (most recent call last):
  File "C:\Users\wogud\OneDrive\Desktop\클로드코드\integrated_management_system\src\features\naver_cafe\adapters.py", line 359, in _get_boards_with_playwright
    await self._page.goto(cafe_info.url, wait_until='networkidle', timeout=20000)
  File "C:\Users\wogud\AppData\Local\Programs\Python\Python313\Lib\site-packages\playwright\async_api\_generated.py", line 8992, in goto
    await self._impl_obj.goto(
        url=url, timeout=timeout, waitUntil=wait_until, referer=referer
    )
  File "C:\Users\wogud\AppData\Local\Programs\Python\Python313\Lib\site-packages\playwright\_impl\_page.py", line 556, in goto
    return await self._main_frame.goto(**locals_to_params(locals()))
           ^^^^^^^^^^^^^^^^^^^^^^^^^^^^^^^^^^^^^^^^^^^^^^^^^^^^^^^^^
  File "C:\Users\wogud\AppData\Local\Programs\Python\Python313\Lib\site-packages\playwright\_impl\_frame.py", line 153, in goto
    await self._channel.send(
        "goto", self._navigation_timeout, locals_to_params(locals())
    )
  File "C:\Users\wogud\AppData\Local\Programs\Python\Python313\Lib\site-packages\playwright\_impl\_connection.py", line 69, in send
    return await self._connection.wrap_api_call(
           ^^^^^^^^^^^^^^^^^^^^^^^^^^^^^^^^^^^^^
    ...<3 lines>...
    )
    ^
  File "C:\Users\wogud\AppData\Local\Programs\Python\Python313\Lib\site-packages\playwright\_impl\_connection.py", line 558, in wrap_api_call
    raise rewrite_error(error, f"{parsed_st['apiName']}: {error}") from None
AttributeError: Page.goto: 'NoneType' object has no attribute 'send'

2025-08-18 00:32:17 - features.naver_cafe.adapters - ERROR - Playwright 게시판 조회 실패: Page.goto: 'NoneType' object has no attribute 'send'
2025-08-18 00:35:06 - features.powerlink_analyzer.adapters - ERROR - PC 크롤링 오류 (브라우저 재사용): 'coroutine' object has no attribute 'goto'
2025-08-18 00:35:07 - features.powerlink_analyzer.adapters - ERROR - PC 크롤링 오류 (브라우저 재사용): 'coroutine' object has no attribute 'goto'
2025-08-18 00:35:07 - features.powerlink_analyzer.adapters - ERROR - PC 크롤링 오류 (브라우저 재사용): 'coroutine' object has no attribute 'goto'
2025-08-18 00:35:08 - features.powerlink_analyzer.adapters - ERROR - PC 크롤링 오류 (브라우저 재사용): 'coroutine' object has no attribute 'goto'
2025-08-18 00:35:09 - features.powerlink_analyzer.adapters - ERROR - PC 크롤링 오류 (브라우저 재사용): 'coroutine' object has no attribute 'goto'
2025-08-18 00:35:09 - features.powerlink_analyzer.adapters - ERROR - PC 크롤링 오류 (브라우저 재사용): 'coroutine' object has no attribute 'goto'
2025-08-18 00:35:12 - features.powerlink_analyzer.adapters - ERROR - PC 크롤링 오류 (브라우저 재사용): 'coroutine' object has no attribute 'goto'
2025-08-18 00:35:12 - features.powerlink_analyzer.adapters - ERROR - PC 크롤링 최대 재시도 횟수 초과 - 기본값 사용
2025-08-18 00:35:12 - features.powerlink_analyzer.adapters - ERROR - MOBILE 크롤링 오류 (브라우저 재사용): 'coroutine' object has no attribute 'goto'
2025-08-18 00:35:13 - features.powerlink_analyzer.adapters - ERROR - PC 크롤링 오류 (브라우저 재사용): 'coroutine' object has no attribute 'goto'
2025-08-18 00:35:13 - features.powerlink_analyzer.adapters - ERROR - PC 크롤링 최대 재시도 횟수 초과 - 기본값 사용
2025-08-18 00:35:13 - features.powerlink_analyzer.adapters - ERROR - MOBILE 크롤링 오류 (브라우저 재사용): 'coroutine' object has no attribute 'goto'
2025-08-18 00:35:13 - features.powerlink_analyzer.adapters - ERROR - PC 크롤링 오류 (브라우저 재사용): 'coroutine' object has no attribute 'goto'
2025-08-18 00:35:13 - features.powerlink_analyzer.adapters - ERROR - PC 크롤링 최대 재시도 횟수 초과 - 기본값 사용
2025-08-18 00:35:13 - features.powerlink_analyzer.adapters - ERROR - MOBILE 크롤링 오류 (브라우저 재사용): 'coroutine' object has no attribute 'goto'
2025-08-18 00:35:14 - features.powerlink_analyzer.adapters - ERROR - MOBILE 크롤링 오류 (브라우저 재사용): 'coroutine' object has no attribute 'goto'
2025-08-18 00:35:15 - features.powerlink_analyzer.adapters - ERROR - MOBILE 크롤링 오류 (브라우저 재사용): 'coroutine' object has no attribute 'goto'
2025-08-18 00:35:15 - features.powerlink_analyzer.adapters - ERROR - MOBILE 크롤링 오류 (브라우저 재사용): 'coroutine' object has no attribute 'goto'
2025-08-18 00:35:18 - features.powerlink_analyzer.adapters - ERROR - MOBILE 크롤링 오류 (브라우저 재사용): 'coroutine' object has no attribute 'goto'
2025-08-18 00:35:18 - features.powerlink_analyzer.adapters - ERROR - MOBILE 크롤링 최대 재시도 횟수 초과 - 기본값 사용
2025-08-18 00:35:18 - features.powerlink_analyzer.worker - ERROR - 키워드 분석 실패: 강아지사료: KeywordAnalysisResult.__init__() got an unexpected keyword argument 'pc_exposure_info'
2025-08-18 00:35:19 - features.powerlink_analyzer.adapters - ERROR - MOBILE 크롤링 오류 (브라우저 재사용): 'coroutine' object has no attribute 'goto'
2025-08-18 00:35:19 - features.powerlink_analyzer.adapters - ERROR - MOBILE 크롤링 최대 재시도 횟수 초과 - 기본값 사용
2025-08-18 00:35:19 - features.powerlink_analyzer.worker - ERROR - 키워드 분석 실패: 오븐베이크: KeywordAnalysisResult.__init__() got an unexpected keyword argument 'pc_exposure_info'
2025-08-18 00:35:19 - features.powerlink_analyzer.adapters - ERROR - MOBILE 크롤링 오류 (브라우저 재사용): 'coroutine' object has no attribute 'goto'
2025-08-18 00:35:19 - features.powerlink_analyzer.adapters - ERROR - MOBILE 크롤링 최대 재시도 횟수 초과 - 기본값 사용
2025-08-18 00:35:19 - features.powerlink_analyzer.worker - ERROR - 키워드 분석 실패: 오븐베이크사료: KeywordAnalysisResult.__init__() got an unexpected keyword argument 'pc_exposure_info'
2025-08-18 00:35:20 - features.powerlink_analyzer.adapters - ERROR - PC 크롤링 오류 (브라우저 재사용): 'coroutine' object has no attribute 'goto'
2025-08-18 00:35:22 - features.powerlink_analyzer.adapters - ERROR - PC 크롤링 오류 (브라우저 재사용): 'coroutine' object has no attribute 'goto'
2025-08-18 00:35:22 - features.powerlink_analyzer.adapters - ERROR - PC 크롤링 오류 (브라우저 재사용): 'coroutine' object has no attribute 'goto'
2025-08-18 00:35:22 - features.powerlink_analyzer.adapters - ERROR - PC 크롤링 오류 (브라우저 재사용): 'coroutine' object has no attribute 'goto'
2025-08-18 00:35:24 - features.powerlink_analyzer.adapters - ERROR - PC 크롤링 오류 (브라우저 재사용): 'coroutine' object has no attribute 'goto'
2025-08-18 00:35:24 - features.powerlink_analyzer.adapters - ERROR - PC 크롤링 오류 (브라우저 재사용): 'coroutine' object has no attribute 'goto'
2025-08-18 00:35:26 - features.powerlink_analyzer.adapters - ERROR - PC 크롤링 오류 (브라우저 재사용): 'coroutine' object has no attribute 'goto'
2025-08-18 00:35:26 - features.powerlink_analyzer.adapters - ERROR - PC 크롤링 최대 재시도 횟수 초과 - 기본값 사용
2025-08-18 00:35:26 - features.powerlink_analyzer.adapters - ERROR - MOBILE 크롤링 오류 (브라우저 재사용): 'coroutine' object has no attribute 'goto'
2025-08-18 00:35:28 - features.powerlink_analyzer.adapters - ERROR - PC 크롤링 오류 (브라우저 재사용): 'coroutine' object has no attribute 'goto'
2025-08-18 00:35:28 - features.powerlink_analyzer.adapters - ERROR - PC 크롤링 최대 재시도 횟수 초과 - 기본값 사용
2025-08-18 00:35:28 - features.powerlink_analyzer.adapters - ERROR - MOBILE 크롤링 오류 (브라우저 재사용): 'coroutine' object has no attribute 'goto'
2025-08-18 00:35:28 - features.powerlink_analyzer.adapters - ERROR - MOBILE 크롤링 오류 (브라우저 재사용): 'coroutine' object has no attribute 'goto'
2025-08-18 00:35:28 - features.powerlink_analyzer.adapters - ERROR - PC 크롤링 오류 (브라우저 재사용): 'coroutine' object has no attribute 'goto'
2025-08-18 00:35:28 - features.powerlink_analyzer.adapters - ERROR - PC 크롤링 최대 재시도 횟수 초과 - 기본값 사용
2025-08-18 00:35:28 - features.powerlink_analyzer.adapters - ERROR - MOBILE 크롤링 오류 (브라우저 재사용): 'coroutine' object has no attribute 'goto'
2025-08-18 00:35:30 - features.powerlink_analyzer.adapters - ERROR - MOBILE 크롤링 오류 (브라우저 재사용): 'coroutine' object has no attribute 'goto'
2025-08-18 00:35:30 - features.powerlink_analyzer.adapters - ERROR - MOBILE 크롤링 오류 (브라우저 재사용): 'coroutine' object has no attribute 'goto'
2025-08-18 09:36:00 - asyncio - ERROR - Task was destroyed but it is pending!
task: <Task pending name='Task-7' coro=<Connection.run() running at C:\Users\wogud\AppData\Local\Programs\Python\Python313\Lib\site-packages\playwright\_impl\_connection.py:312> wait_for=<Future pending cb=[Task.task_wakeup()]>>
2025-08-18 10:24:06 - main - ERROR - 기능 모듈 로드 실패: 'PowerLinkResultsWidget' object has no attribute 'display_results'
2025-08-18 10:24:06 - main - ERROR - 상세 오류: Traceback (most recent call last):
  File "c:\Users\wogud\OneDrive\Desktop\클로드코드\integrated_management_system\main.py", line 42, in load_features
    register_powerlink(app)
    ~~~~~~~~~~~~~~~~~~^^^^^
  File "c:\Users\wogud\OneDrive\Desktop\클로드코드\integrated_management_system\src\features\powerlink_analyzer\__init__.py", line 14, in register
    widget = PowerLinkAnalyzerWidget()
  File "c:\Users\wogud\OneDrive\Desktop\클로드코드\integrated_management_system\src\features\powerlink_analyzer\ui.py", line 23, in __init__
    self.setup_connections()
    ~~~~~~~~~~~~~~~~~~~~~~^^
  File "c:\Users\wogud\OneDrive\Desktop\클로드코드\integrated_management_system\src\features\powerlink_analyzer\ui.py", line 139, in setup_connections
    self.control_widget.analysis_completed.connect(self.results_widget.display_results)
                                                   ^^^^^^^^^^^^^^^^^^^^^^^^^^^^^^^^^^^
AttributeError: 'PowerLinkResultsWidget' object has no attribute 'display_results'

2025-08-18 10:24:06 - desktop.app - ERROR - 애플리케이션 실행 실패: 'PowerLinkResultsWidget' object has no attribute 'display_results'
2025-08-18 10:24:06 - main - ERROR - 애플리케이션 시작 실패: 'PowerLinkResultsWidget' object has no attribute 'display_results'
2025-08-18 10:24:09 - main - ERROR - 기능 모듈 로드 실패: 'PowerLinkResultsWidget' object has no attribute 'display_results'
2025-08-18 10:24:09 - main - ERROR - 상세 오류: Traceback (most recent call last):
  File "c:\Users\wogud\OneDrive\Desktop\클로드코드\integrated_management_system\main.py", line 42, in load_features
    register_powerlink(app)
    ~~~~~~~~~~~~~~~~~~^^^^^
  File "c:\Users\wogud\OneDrive\Desktop\클로드코드\integrated_management_system\src\features\powerlink_analyzer\__init__.py", line 14, in register
    widget = PowerLinkAnalyzerWidget()
  File "c:\Users\wogud\OneDrive\Desktop\클로드코드\integrated_management_system\src\features\powerlink_analyzer\ui.py", line 23, in __init__
    self.setup_connections()
    ~~~~~~~~~~~~~~~~~~~~~~^^
  File "c:\Users\wogud\OneDrive\Desktop\클로드코드\integrated_management_system\src\features\powerlink_analyzer\ui.py", line 139, in setup_connections
    self.control_widget.analysis_completed.connect(self.results_widget.display_results)
                                                   ^^^^^^^^^^^^^^^^^^^^^^^^^^^^^^^^^^^
AttributeError: 'PowerLinkResultsWidget' object has no attribute 'display_results'

2025-08-18 10:24:09 - desktop.app - ERROR - 애플리케이션 실행 실패: 'PowerLinkResultsWidget' object has no attribute 'display_results'
2025-08-18 10:24:09 - main - ERROR - 애플리케이션 시작 실패: 'PowerLinkResultsWidget' object has no attribute 'display_results'
2025-08-18 10:24:44 - main - ERROR - 기능 모듈 로드 실패: 'PowerLinkResultsWidget' object has no attribute 'update_progress'
2025-08-18 10:24:44 - main - ERROR - 상세 오류: Traceback (most recent call last):
  File "C:\Users\wogud\OneDrive\Desktop\클로드코드\integrated_management_system\main.py", line 42, in load_features
    register_powerlink(app)
    ~~~~~~~~~~~~~~~~~~^^^^^
  File "C:\Users\wogud\OneDrive\Desktop\클로드코드\integrated_management_system\src\features\powerlink_analyzer\__init__.py", line 14, in register
    widget = PowerLinkAnalyzerWidget()
  File "C:\Users\wogud\OneDrive\Desktop\클로드코드\integrated_management_system\src\features\powerlink_analyzer\ui.py", line 23, in __init__
    self.setup_connections()
    ~~~~~~~~~~~~~~~~~~~~~~^^
  File "C:\Users\wogud\OneDrive\Desktop\클로드코드\integrated_management_system\src\features\powerlink_analyzer\ui.py", line 140, in setup_connections
    self.control_widget.analysis_progress_updated.connect(self.results_widget.update_progress)
                                                          ^^^^^^^^^^^^^^^^^^^^^^^^^^^^^^^^^^^
AttributeError: 'PowerLinkResultsWidget' object has no attribute 'update_progress'

2025-08-18 10:24:44 - desktop.app - ERROR - 애플리케이션 실행 실패: 'PowerLinkResultsWidget' object has no attribute 'update_progress'
2025-08-18 10:24:44 - main - ERROR - 애플리케이션 시작 실패: 'PowerLinkResultsWidget' object has no attribute 'update_progress'
2025-08-18 10:26:31 - main - ERROR - 기능 모듈 로드 실패: 'PowerLinkResultsWidget' object has no attribute 'add_keyword_result'
2025-08-18 10:26:31 - main - ERROR - 상세 오류: Traceback (most recent call last):
  File "C:\Users\wogud\OneDrive\Desktop\클로드코드\integrated_management_system\main.py", line 42, in load_features
    register_powerlink(app)
    ~~~~~~~~~~~~~~~~~~^^^^^
  File "C:\Users\wogud\OneDrive\Desktop\클로드코드\integrated_management_system\src\features\powerlink_analyzer\__init__.py", line 14, in register
    widget = PowerLinkAnalyzerWidget()
  File "C:\Users\wogud\OneDrive\Desktop\클로드코드\integrated_management_system\src\features\powerlink_analyzer\ui.py", line 23, in __init__
    self.setup_connections()
    ~~~~~~~~~~~~~~~~~~~~~~^^
  File "C:\Users\wogud\OneDrive\Desktop\클로드코드\integrated_management_system\src\features\powerlink_analyzer\ui.py", line 143, in setup_connections
    self.control_widget.keyword_result_ready.connect(self.results_widget.add_keyword_result)
                                                     ^^^^^^^^^^^^^^^^^^^^^^^^^^^^^^^^^^^^^^
AttributeError: 'PowerLinkResultsWidget' object has no attribute 'add_keyword_result'

2025-08-18 10:26:31 - desktop.app - ERROR - 애플리케이션 실행 실패: 'PowerLinkResultsWidget' object has no attribute 'add_keyword_result'
2025-08-18 10:26:31 - main - ERROR - 애플리케이션 시작 실패: 'PowerLinkResultsWidget' object has no attribute 'add_keyword_result'
2025-08-18 10:29:03 - main - ERROR - 기능 모듈 로드 실패: 'PowerLinkResultsWidget' object has no attribute 'update_keyword_partial'
2025-08-18 10:29:03 - main - ERROR - 상세 오류: Traceback (most recent call last):
  File "C:\Users\wogud\OneDrive\Desktop\클로드코드\integrated_management_system\main.py", line 42, in load_features
    register_powerlink(app)
    ~~~~~~~~~~~~~~~~~~^^^^^
  File "C:\Users\wogud\OneDrive\Desktop\클로드코드\integrated_management_system\src\features\powerlink_analyzer\__init__.py", line 14, in register
    widget = PowerLinkAnalyzerWidget()
  File "C:\Users\wogud\OneDrive\Desktop\클로드코드\integrated_management_system\src\features\powerlink_analyzer\ui.py", line 23, in __init__
    self.setup_connections()
    ~~~~~~~~~~~~~~~~~~~~~~^^
  File "C:\Users\wogud\OneDrive\Desktop\클로드코드\integrated_management_system\src\features\powerlink_analyzer\ui.py", line 144, in setup_connections
    self.control_widget.keyword_partial_ready.connect(self.results_widget.update_keyword_partial)
                                                      ^^^^^^^^^^^^^^^^^^^^^^^^^^^^^^^^^^^^^^^^^^
AttributeError: 'PowerLinkResultsWidget' object has no attribute 'update_keyword_partial'. Did you mean: 'update_keyword_data'?

2025-08-18 10:29:03 - desktop.app - ERROR - 애플리케이션 실행 실패: 'PowerLinkResultsWidget' object has no attribute 'update_keyword_partial'
2025-08-18 10:29:03 - main - ERROR - 애플리케이션 시작 실패: 'PowerLinkResultsWidget' object has no attribute 'update_keyword_partial'
2025-08-18 10:29:46 - main - ERROR - 기능 모듈 로드 실패: 'PowerLinkResultsWidget' object has no attribute 'update_keyword_partial'
2025-08-18 10:29:46 - main - ERROR - 상세 오류: Traceback (most recent call last):
  File "C:\Users\wogud\OneDrive\Desktop\클로드코드\integrated_management_system\main.py", line 42, in load_features
    register_powerlink(app)
    ~~~~~~~~~~~~~~~~~~^^^^^
  File "C:\Users\wogud\OneDrive\Desktop\클로드코드\integrated_management_system\src\features\powerlink_analyzer\__init__.py", line 14, in register
    widget = PowerLinkAnalyzerWidget()
  File "C:\Users\wogud\OneDrive\Desktop\클로드코드\integrated_management_system\src\features\powerlink_analyzer\ui.py", line 23, in __init__
    self.setup_connections()
    ~~~~~~~~~~~~~~~~~~~~~~^^
  File "C:\Users\wogud\OneDrive\Desktop\클로드코드\integrated_management_system\src\features\powerlink_analyzer\ui.py", line 144, in setup_connections
    self.control_widget.keyword_partial_ready.connect(self.results_widget.update_keyword_partial)
                                                      ^^^^^^^^^^^^^^^^^^^^^^^^^^^^^^^^^^^^^^^^^^
AttributeError: 'PowerLinkResultsWidget' object has no attribute 'update_keyword_partial'. Did you mean: 'update_keyword_data'?

2025-08-18 10:29:46 - desktop.app - ERROR - 애플리케이션 실행 실패: 'PowerLinkResultsWidget' object has no attribute 'update_keyword_partial'
2025-08-18 10:29:46 - main - ERROR - 애플리케이션 시작 실패: 'PowerLinkResultsWidget' object has no attribute 'update_keyword_partial'
2025-08-18 10:41:19 - features.powerlink_analyzer.worker - ERROR - API 호출 실패: 강아지간식: 'cp949' codec can't encode character '\U0001f50d' in position 0: illegal multibyte sequence
2025-08-18 10:41:20 - features.powerlink_analyzer.worker - ERROR - API 호출 실패: 강아지수제간식: 'cp949' codec can't encode character '\U0001f50d' in position 0: illegal multibyte sequence
2025-08-18 10:41:21 - features.powerlink_analyzer.worker - ERROR - API 호출 실패: 애견간식: 'cp949' codec can't encode character '\U0001f50d' in position 0: illegal multibyte sequence
2025-08-18 10:41:23 - features.powerlink_analyzer.worker - ERROR - API 호출 실패: 강아지보양식: 'cp949' codec can't encode character '\U0001f50d' in position 0: illegal multibyte sequence
2025-08-18 10:41:24 - features.powerlink_analyzer.worker - ERROR - API 호출 실패: 애견수제간식: 'cp949' codec can't encode character '\U0001f50d' in position 0: illegal multibyte sequence
2025-08-18 10:44:50 - features.powerlink_analyzer.worker - ERROR - API 호출 실패: 강아지간식: 'cp949' codec can't encode character '\U0001f50d' in position 0: illegal multibyte sequence
2025-08-18 10:44:51 - features.powerlink_analyzer.worker - ERROR - API 호출 실패: 강아지수제간식: 'cp949' codec can't encode character '\U0001f50d' in position 0: illegal multibyte sequence
2025-08-18 10:44:51 - features.powerlink_analyzer.worker - ERROR - API 호출 실패: 애견간식: 'cp949' codec can't encode character '\U0001f50d' in position 0: illegal multibyte sequence
2025-08-18 10:44:54 - features.powerlink_analyzer.worker - ERROR - API 호출 실패: 강아지보양식: 'cp949' codec can't encode character '\U0001f50d' in position 0: illegal multibyte sequence
2025-08-18 10:44:54 - features.powerlink_analyzer.worker - ERROR - API 호출 실패: 애견수제간식: 'cp949' codec can't encode character '\U0001f50d' in position 0: illegal multibyte sequence
2025-08-18 10:47:20 - features.powerlink_analyzer.worker - ERROR - 워커1 크롤링 실패: 강아지간식 (pc): 'PowerLinkAnalysisWorker' object has no attribute 'keyword_partial_ready'
2025-08-18 10:47:20 - features.powerlink_analyzer.worker - ERROR - 워커2 크롤링 실패: 강아지간식 (mobile): 'PowerLinkAnalysisWorker' object has no attribute 'keyword_partial_ready'
2025-08-18 10:47:20 - features.powerlink_analyzer.worker - ERROR - 워커1 크롤링 실패: 강아지수제간식 (pc): 'PowerLinkAnalysisWorker' object has no attribute 'keyword_partial_ready'
2025-08-18 10:47:21 - features.powerlink_analyzer.worker - ERROR - 워커2 크롤링 실패: 강아지수제간식 (mobile): 'PowerLinkAnalysisWorker' object has no attribute 'keyword_partial_ready'
2025-08-18 10:47:21 - features.powerlink_analyzer.worker - ERROR - 워커1 크롤링 실패: 애견간식 (pc): 'PowerLinkAnalysisWorker' object has no attribute 'keyword_partial_ready'
2025-08-18 10:47:22 - features.powerlink_analyzer.worker - ERROR - 워커1 크롤링 실패: 강아지보양식 (pc): 'PowerLinkAnalysisWorker' object has no attribute 'keyword_partial_ready'
2025-08-18 10:47:22 - features.powerlink_analyzer.worker - ERROR - 워커2 크롤링 실패: 애견간식 (mobile): 'PowerLinkAnalysisWorker' object has no attribute 'keyword_partial_ready'
2025-08-18 10:47:23 - features.powerlink_analyzer.worker - ERROR - 워커1 크롤링 실패: 강아지보양식 (mobile): 'PowerLinkAnalysisWorker' object has no attribute 'keyword_partial_ready'
2025-08-18 10:47:23 - features.powerlink_analyzer.worker - ERROR - 워커2 크롤링 실패: 애견수제간식 (pc): 'PowerLinkAnalysisWorker' object has no attribute 'keyword_partial_ready'
2025-08-18 10:47:23 - features.powerlink_analyzer.worker - ERROR - API 호출 실패: 강아지간식: 'cp949' codec can't encode character '\U0001f50d' in position 0: illegal multibyte sequence
2025-08-18 10:47:23 - features.powerlink_analyzer.worker - ERROR - 워커1 크롤링 실패: 애견수제간식 (mobile): 'PowerLinkAnalysisWorker' object has no attribute 'keyword_partial_ready'
2025-08-18 10:47:24 - features.powerlink_analyzer.worker - ERROR - API 호출 실패: 강아지수제간식: 'cp949' codec can't encode character '\U0001f50d' in position 0: illegal multibyte sequence
2025-08-18 10:47:24 - features.powerlink_analyzer.worker - ERROR - API 호출 실패: 애견간식: 'cp949' codec can't encode character '\U0001f50d' in position 0: illegal multibyte sequence
2025-08-18 10:47:27 - features.powerlink_analyzer.worker - ERROR - API 호출 실패: 강아지보양식: 'cp949' codec can't encode character '\U0001f50d' in position 0: illegal multibyte sequence
2025-08-18 10:47:28 - features.powerlink_analyzer.worker - ERROR - API 호출 실패: 애견수제간식: 'cp949' codec can't encode character '\U0001f50d' in position 0: illegal multibyte sequence
2025-08-18 10:54:04 - main - ERROR - 기능 모듈 로드 실패: 'PowerLinkResultsWidget' object has no attribute 'display_results'
2025-08-18 10:54:04 - main - ERROR - 상세 오류: Traceback (most recent call last):
  File "C:\Users\wogud\OneDrive\Desktop\클로드코드\integrated_management_system\main.py", line 42, in load_features
    register_powerlink(app)
    ~~~~~~~~~~~~~~~~~~^^^^^
  File "C:\Users\wogud\OneDrive\Desktop\클로드코드\integrated_management_system\src\features\powerlink_analyzer\__init__.py", line 14, in register
    widget = PowerLinkAnalyzerWidget()
  File "C:\Users\wogud\OneDrive\Desktop\클로드코드\integrated_management_system\src\features\powerlink_analyzer\ui.py", line 23, in __init__
    self.setup_connections()
    ~~~~~~~~~~~~~~~~~~~~~~^^
  File "C:\Users\wogud\OneDrive\Desktop\클로드코드\integrated_management_system\src\features\powerlink_analyzer\ui.py", line 140, in setup_connections
    self.control_widget.analysis_completed.connect(self.results_widget.display_results)
                                                   ^^^^^^^^^^^^^^^^^^^^^^^^^^^^^^^^^^^
AttributeError: 'PowerLinkResultsWidget' object has no attribute 'display_results'

2025-08-18 10:54:04 - desktop.app - ERROR - 애플리케이션 실행 실패: 'PowerLinkResultsWidget' object has no attribute 'display_results'
2025-08-18 10:54:04 - main - ERROR - 애플리케이션 시작 실패: 'PowerLinkResultsWidget' object has no attribute 'display_results'
2025-08-18 11:06:56 - asyncio - ERROR - Task was destroyed but it is pending!
task: <Task pending name='Task-7' coro=<Connection.run() running at C:\Users\wogud\AppData\Local\Programs\Python\Python313\Lib\site-packages\playwright\_impl\_connection.py:312> wait_for=<Future pending cb=[Task.task_wakeup()]>>
2025-08-18 11:33:03 - foundation.db - ERROR - DB 연결 오류: 'KeywordAnalysisResult' object has no attribute 'monthly_search_volume'
2025-08-18 11:33:03 - features.powerlink_analyzer.results_widget - ERROR - PowerLink 분석 세션 저장 실패: 'KeywordAnalysisResult' object has no attribute 'monthly_search_volume'
2025-08-18 11:33:04 - foundation.db - ERROR - DB 연결 오류: 'KeywordAnalysisResult' object has no attribute 'monthly_search_volume'
2025-08-18 11:33:04 - features.powerlink_analyzer.results_widget - ERROR - PowerLink 분석 세션 저장 실패: 'KeywordAnalysisResult' object has no attribute 'monthly_search_volume'
2025-08-18 11:59:27 - main - ERROR - 기능 모듈 로드 실패: 'PowerLinkResultsWidget' object has no attribute 'add_keyword_immediately'
2025-08-18 11:59:27 - main - ERROR - 상세 오류: Traceback (most recent call last):
  File "c:\Users\wogud\OneDrive\Desktop\클로드코드\integrated_management_system\main.py", line 42, in load_features
    register_powerlink(app)
    ~~~~~~~~~~~~~~~~~~^^^^^
  File "c:\Users\wogud\OneDrive\Desktop\클로드코드\integrated_management_system\src\features\powerlink_analyzer\__init__.py", line 14, in register
    widget = PowerLinkAnalyzerWidget()
  File "c:\Users\wogud\OneDrive\Desktop\클로드코드\integrated_management_system\src\features\powerlink_analyzer\ui.py", line 23, in __init__
    self.setup_connections()
    ~~~~~~~~~~~~~~~~~~~~~~^^
  File "c:\Users\wogud\OneDrive\Desktop\클로드코드\integrated_management_system\src\features\powerlink_analyzer\ui.py", line 144, in setup_connections
    self.control_widget.keyword_added_immediately.connect(self.results_widget.add_keyword_immediately)
                                                          ^^^^^^^^^^^^^^^^^^^^^^^^^^^^^^^^^^^^^^^^^^^
AttributeError: 'PowerLinkResultsWidget' object has no attribute 'add_keyword_immediately'

2025-08-18 11:59:27 - desktop.app - ERROR - 애플리케이션 실행 실패: 'PowerLinkResultsWidget' object has no attribute 'add_keyword_immediately'
2025-08-18 11:59:27 - main - ERROR - 애플리케이션 시작 실패: 'PowerLinkResultsWidget' object has no attribute 'add_keyword_immediately'
2025-08-18 12:00:04 - main - ERROR - 기능 모듈 로드 실패: 'PowerLinkResultsWidget' object has no attribute 'add_keyword_immediately'
2025-08-18 12:00:04 - main - ERROR - 상세 오류: Traceback (most recent call last):
  File "C:\Users\wogud\OneDrive\Desktop\클로드코드\integrated_management_system\main.py", line 42, in load_features
    register_powerlink(app)
    ~~~~~~~~~~~~~~~~~~^^^^^
  File "C:\Users\wogud\OneDrive\Desktop\클로드코드\integrated_management_system\src\features\powerlink_analyzer\__init__.py", line 14, in register
    widget = PowerLinkAnalyzerWidget()
  File "C:\Users\wogud\OneDrive\Desktop\클로드코드\integrated_management_system\src\features\powerlink_analyzer\ui.py", line 23, in __init__
    self.setup_connections()
    ~~~~~~~~~~~~~~~~~~~~~~^^
  File "C:\Users\wogud\OneDrive\Desktop\클로드코드\integrated_management_system\src\features\powerlink_analyzer\ui.py", line 144, in setup_connections
    self.control_widget.keyword_added_immediately.connect(self.results_widget.add_keyword_immediately)
                                                          ^^^^^^^^^^^^^^^^^^^^^^^^^^^^^^^^^^^^^^^^^^^
AttributeError: 'PowerLinkResultsWidget' object has no attribute 'add_keyword_immediately'

2025-08-18 12:00:04 - desktop.app - ERROR - 애플리케이션 실행 실패: 'PowerLinkResultsWidget' object has no attribute 'add_keyword_immediately'
2025-08-18 12:00:04 - main - ERROR - 애플리케이션 시작 실패: 'PowerLinkResultsWidget' object has no attribute 'add_keyword_immediately'
2025-08-18 12:20:06 - asyncio - ERROR - Task was destroyed but it is pending!
task: <Task pending name='Task-7' coro=<Connection.run() running at C:\Users\wogud\AppData\Local\Programs\Python\Python313\Lib\site-packages\playwright\_impl\_connection.py:312> wait_for=<Future pending cb=[Task.task_wakeup()]>>
2025-08-18 12:23:40 - asyncio - ERROR - Task was destroyed but it is pending!
task: <Task pending name='Task-7' coro=<Connection.run() running at C:\Users\wogud\AppData\Local\Programs\Python\Python313\Lib\site-packages\playwright\_impl\_connection.py:312> wait_for=<Future pending cb=[Task.task_wakeup()]>>
2025-08-18 12:24:24 - asyncio - ERROR - Task was destroyed but it is pending!
task: <Task pending name='Task-552' coro=<Connection.run() running at C:\Users\wogud\AppData\Local\Programs\Python\Python313\Lib\site-packages\playwright\_impl\_connection.py:312> wait_for=<Future pending cb=[Task.task_wakeup()]>>
2025-08-18 12:42:52 - asyncio - ERROR - Task was destroyed but it is pending!
task: <Task pending name='Task-104' coro=<Connection.run() running at C:\Users\wogud\AppData\Local\Programs\Python\Python313\Lib\site-packages\playwright\_impl\_connection.py:312> wait_for=<Future pending cb=[Task.task_wakeup()]>>
2025-08-18 12:43:46 - asyncio - ERROR - Task was destroyed but it is pending!
task: <Task pending name='Task-410' coro=<Connection.run() running at C:\Users\wogud\AppData\Local\Programs\Python\Python313\Lib\site-packages\playwright\_impl\_connection.py:312> wait_for=<Future pending cb=[Task.task_wakeup()]>>
2025-08-18 12:44:38 - asyncio - ERROR - Task was destroyed but it is pending!
task: <Task pending name='Task-7' coro=<Connection.run() running at C:\Users\wogud\AppData\Local\Programs\Python\Python313\Lib\site-packages\playwright\_impl\_connection.py:312> wait_for=<Future pending cb=[Task.task_wakeup()]>>
2025-08-18 12:49:10 - asyncio - ERROR - Task was destroyed but it is pending!
task: <Task pending name='Task-7' coro=<Connection.run() running at C:\Users\wogud\AppData\Local\Programs\Python\Python313\Lib\site-packages\playwright\_impl\_connection.py:312> wait_for=<Future pending cb=[Task.task_wakeup()]>>
2025-08-18 12:50:09 - asyncio - ERROR - Task was destroyed but it is pending!
task: <Task pending name='Task-335' coro=<Connection.run() running at C:\Users\wogud\AppData\Local\Programs\Python\Python313\Lib\site-packages\playwright\_impl\_connection.py:312> wait_for=<Future pending cb=[Task.task_wakeup()]>>
2025-08-18 12:50:09 - asyncio - ERROR - Task was destroyed but it is pending!
task: <Task pending name='Task-417' coro=<Connection.run() running at C:\Users\wogud\AppData\Local\Programs\Python\Python313\Lib\site-packages\playwright\_impl\_connection.py:312> wait_for=<Future pending cb=[Task.task_wakeup()]>>
2025-08-18 12:50:09 - asyncio - ERROR - Task was destroyed but it is pending!
task: <Task pending name='Task-484' coro=<Connection.run() running at C:\Users\wogud\AppData\Local\Programs\Python\Python313\Lib\site-packages\playwright\_impl\_connection.py:312> wait_for=<Future pending cb=[Task.task_wakeup()]>>
2025-08-18 12:50:30 - asyncio - ERROR - Task was destroyed but it is pending!
task: <Task pending name='Task-7' coro=<Connection.run() running at C:\Users\wogud\AppData\Local\Programs\Python\Python313\Lib\site-packages\playwright\_impl\_connection.py:312> wait_for=<Future pending cb=[Task.task_wakeup()]>>
2025-08-18 19:07:52 - features.keyword_analysis - ERROR - 키워드 분석 기능 등록 실패: No module named 'src.features.keyword_analysis.text_ops'
2025-08-18 19:07:52 - main - ERROR - 기능 모듈 로드 실패: No module named 'src.features.keyword_analysis.text_ops'
2025-08-18 19:07:52 - main - ERROR - 상세 오류: Traceback (most recent call last):
  File "c:\Users\wogud\OneDrive\Desktop\클로드코드\integrated_management_system\main.py", line 24, in load_features
    register_keyword_analysis(app)
    ~~~~~~~~~~~~~~~~~~~~~~~~~^^^^^
  File "c:\Users\wogud\OneDrive\Desktop\클로드코드\integrated_management_system\src\features\keyword_analysis\__init__.py", line 16, in register
    from .ui import KeywordAnalysisWidget
  File "c:\Users\wogud\OneDrive\Desktop\클로드코드\integrated_management_system\src\features\keyword_analysis\ui.py", line 23, in <module>
    from .text_ops import parse_keywords_from_text, filter_duplicates, clean_keywords, filter_unique_keywords_with_skipped
ModuleNotFoundError: No module named 'src.features.keyword_analysis.text_ops'

2025-08-18 19:07:52 - desktop.app - ERROR - 애플리케이션 실행 실패: No module named 'src.features.keyword_analysis.text_ops'
2025-08-18 19:07:52 - main - ERROR - 애플리케이션 시작 실패: No module named 'src.features.keyword_analysis.text_ops'
2025-08-18 20:42:28 - features.keyword_analysis - ERROR - 키워드 분석 기능 등록 실패: cannot import name 'AnalysisConfig' from 'src.features.keyword_analysis.models' (c:\Users\wogud\OneDrive\Desktop\클로드코드\integrated_management_system\src\features\keyword_analysis\models.py)
2025-08-18 20:42:28 - main - ERROR - 기능 모듈 로드 실패: cannot import name 'AnalysisConfig' from 'src.features.keyword_analysis.models' (c:\Users\wogud\OneDrive\Desktop\클로드코드\integrated_management_system\src\features\keyword_analysis\models.py)
2025-08-18 20:42:28 - main - ERROR - 상세 오류: Traceback (most recent call last):
  File "c:\Users\wogud\OneDrive\Desktop\클로드코드\integrated_management_system\main.py", line 24, in load_features
    register_keyword_analysis(app)
    ~~~~~~~~~~~~~~~~~~~~~~~~~^^^^^
  File "c:\Users\wogud\OneDrive\Desktop\클로드코드\integrated_management_system\src\features\keyword_analysis\__init__.py", line 16, in register
    from .ui import KeywordAnalysisWidget
  File "c:\Users\wogud\OneDrive\Desktop\클로드코드\integrated_management_system\src\features\keyword_analysis\ui.py", line 26, in <module>
    from .models import KeywordData, AnalysisConfig, AnalysisProgress
ImportError: cannot import name 'AnalysisConfig' from 'src.features.keyword_analysis.models' (c:\Users\wogud\OneDrive\Desktop\클로드코드\integrated_management_system\src\features\keyword_analysis\models.py)

2025-08-18 20:42:28 - desktop.app - ERROR - 애플리케이션 실행 실패: cannot import name 'AnalysisConfig' from 'src.features.keyword_analysis.models' (c:\Users\wogud\OneDrive\Desktop\클로드코드\integrated_management_system\src\features\keyword_analysis\models.py)
2025-08-18 20:42:28 - main - ERROR - 애플리케이션 시작 실패: cannot import name 'AnalysisConfig' from 'src.features.keyword_analysis.models' (c:\Users\wogud\OneDrive\Desktop\클로드코드\integrated_management_system\src\features\keyword_analysis\models.py)
2025-08-18 20:43:24 - vendors.naver.search_shop - ERROR - search_shop API 호출 실패: Request failed: 401 Client Error: Unauthorized for url: https://openapi.naver.com/v1/search/shop.json?query=%EB%85%B8%EB%A0%B9%EA%B2%AC%ED%99%94%EC%8B%9D&display=40&start=1&sort=sim
2025-08-18 20:43:24 - vendors.naver.shopping - ERROR - 네이버 쇼핑 API 호출 실패: API 호출 실패: Request failed: 401 Client Error: Unauthorized for url: https://openapi.naver.com/v1/search/shop.json?query=%EB%85%B8%EB%A0%B9%EA%B2%AC%ED%99%94%EC%8B%9D&display=40&start=1&sort=sim
2025-08-18 20:43:25 - vendors.naver.search_shop - ERROR - search_shop API 호출 실패: Request failed: 401 Client Error: Unauthorized for url: https://openapi.naver.com/v1/search/shop.json?query=%EB%B0%98%EB%A0%A4%EA%B2%AC%ED%99%94%EC%8B%9D&display=40&start=1&sort=sim
2025-08-18 20:43:25 - vendors.naver.shopping - ERROR - 네이버 쇼핑 API 호출 실패: API 호출 실패: Request failed: 401 Client Error: Unauthorized for url: https://openapi.naver.com/v1/search/shop.json?query=%EB%B0%98%EB%A0%A4%EA%B2%AC%ED%99%94%EC%8B%9D&display=40&start=1&sort=sim
2025-08-18 20:43:26 - vendors.naver.search_shop - ERROR - search_shop API 호출 실패: Request failed: 401 Client Error: Unauthorized for url: https://openapi.naver.com/v1/search/shop.json?query=%ED%99%94%EC%8B%9D%EA%B0%95%EC%95%84%EC%A7%80&display=40&start=1&sort=sim
2025-08-18 20:43:26 - vendors.naver.shopping - ERROR - 네이버 쇼핑 API 호출 실패: API 호출 실패: Request failed: 401 Client Error: Unauthorized for url: https://openapi.naver.com/v1/search/shop.json?query=%ED%99%94%EC%8B%9D%EA%B0%95%EC%95%84%EC%A7%80&display=40&start=1&sort=sim
2025-08-18 20:43:26 - vendors.naver.search_shop - ERROR - search_shop API 호출 실패: Request failed: 401 Client Error: Unauthorized for url: https://openapi.naver.com/v1/search/shop.json?query=%EC%95%A0%EA%B2%AC%EC%83%9D%EC%8B%9D&display=40&start=1&sort=sim
2025-08-18 20:43:26 - vendors.naver.shopping - ERROR - 네이버 쇼핑 API 호출 실패: API 호출 실패: Request failed: 401 Client Error: Unauthorized for url: https://openapi.naver.com/v1/search/shop.json?query=%EC%95%A0%EA%B2%AC%EC%83%9D%EC%8B%9D&display=40&start=1&sort=sim
2025-08-18 20:43:26 - vendors.naver.search_shop - ERROR - search_shop API 호출 실패: Request failed: 401 Client Error: Unauthorized for url: https://openapi.naver.com/v1/search/shop.json?query=%EA%B0%95%EC%95%84%EC%A7%80%EC%9E%90%EC%97%B0%ED%99%94%EC%8B%9D&display=40&start=1&sort=sim
2025-08-18 20:43:26 - vendors.naver.shopping - ERROR - 네이버 쇼핑 API 호출 실패: API 호출 실패: Request failed: 401 Client Error: Unauthorized for url: https://openapi.naver.com/v1/search/shop.json?query=%EA%B0%95%EC%95%84%EC%A7%80%EC%9E%90%EC%97%B0%ED%99%94%EC%8B%9D&display=40&start=1&sort=sim
2025-08-18 20:43:26 - vendors.naver.search_shop - ERROR - search_shop API 호출 실패: Request failed: 401 Client Error: Unauthorized for url: https://openapi.naver.com/v1/search/shop.json?query=%EA%B0%95%EC%95%84%EC%A7%80%EB%8B%AD%EA%B3%A0%EA%B8%B0%ED%99%94%EC%8B%9D&display=40&start=1&sort=sim
2025-08-18 20:43:26 - vendors.naver.shopping - ERROR - 네이버 쇼핑 API 호출 실패: API 호출 실패: Request failed: 401 Client Error: Unauthorized for url: https://openapi.naver.com/v1/search/shop.json?query=%EA%B0%95%EC%95%84%EC%A7%80%EB%8B%AD%EA%B3%A0%EA%B8%B0%ED%99%94%EC%8B%9D&display=40&start=1&sort=sim
2025-08-18 20:43:26 - vendors.naver.search_shop - ERROR - search_shop API 호출 실패: Request failed: 401 Client Error: Unauthorized for url: https://openapi.naver.com/v1/search/shop.json?query=%EB%8C%80%ED%98%95%EA%B2%AC%ED%99%94%EC%8B%9D&display=40&start=1&sort=sim
2025-08-18 20:43:26 - vendors.naver.shopping - ERROR - 네이버 쇼핑 API 호출 실패: API 호출 실패: Request failed: 401 Client Error: Unauthorized for url: https://openapi.naver.com/v1/search/shop.json?query=%EB%8C%80%ED%98%95%EA%B2%AC%ED%99%94%EC%8B%9D&display=40&start=1&sort=sim
2025-08-18 20:43:27 - vendors.naver.search_shop - ERROR - search_shop API 호출 실패: Request failed: 401 Client Error: Unauthorized for url: https://openapi.naver.com/v1/search/shop.json?query=%EC%86%8C%ED%98%95%EA%B2%AC%ED%99%94%EC%8B%9D&display=40&start=1&sort=sim
2025-08-18 20:43:27 - vendors.naver.shopping - ERROR - 네이버 쇼핑 API 호출 실패: API 호출 실패: Request failed: 401 Client Error: Unauthorized for url: https://openapi.naver.com/v1/search/shop.json?query=%EC%86%8C%ED%98%95%EA%B2%AC%ED%99%94%EC%8B%9D&display=40&start=1&sort=sim
2025-08-18 20:44:28 - vendors.naver.search_shop - ERROR - search_shop API 호출 실패: Request failed: 401 Client Error: Unauthorized for url: https://openapi.naver.com/v1/search/shop.json?query=%EB%8C%80%ED%98%95%EA%B2%AC%ED%99%94%EC%8B%9D&display=40&start=1&sort=sim
2025-08-18 20:44:28 - vendors.naver.shopping - ERROR - 네이버 쇼핑 API 호출 실패: API 호출 실패: Request failed: 401 Client Error: Unauthorized for url: https://openapi.naver.com/v1/search/shop.json?query=%EB%8C%80%ED%98%95%EA%B2%AC%ED%99%94%EC%8B%9D&display=40&start=1&sort=sim
2025-08-18 20:44:29 - vendors.naver.search_shop - ERROR - search_shop API 호출 실패: Request failed: 401 Client Error: Unauthorized for url: https://openapi.naver.com/v1/search/shop.json?query=%EC%95%A0%EA%B2%AC%EC%83%9D%EC%8B%9D&display=40&start=1&sort=sim
2025-08-18 20:44:29 - vendors.naver.shopping - ERROR - 네이버 쇼핑 API 호출 실패: API 호출 실패: Request failed: 401 Client Error: Unauthorized for url: https://openapi.naver.com/v1/search/shop.json?query=%EC%95%A0%EA%B2%AC%EC%83%9D%EC%8B%9D&display=40&start=1&sort=sim
2025-08-18 20:44:30 - vendors.naver.search_shop - ERROR - search_shop API 호출 실패: Request failed: 401 Client Error: Unauthorized for url: https://openapi.naver.com/v1/search/shop.json?query=%EA%B0%95%EC%95%84%EC%A7%80%EC%9E%90%EC%97%B0%ED%99%94%EC%8B%9D&display=40&start=1&sort=sim
2025-08-18 20:44:30 - vendors.naver.shopping - ERROR - 네이버 쇼핑 API 호출 실패: API 호출 실패: Request failed: 401 Client Error: Unauthorized for url: https://openapi.naver.com/v1/search/shop.json?query=%EA%B0%95%EC%95%84%EC%A7%80%EC%9E%90%EC%97%B0%ED%99%94%EC%8B%9D&display=40&start=1&sort=sim
2025-08-18 21:26:56 - main - ERROR - 기능 모듈 로드 실패: cannot import name 'ModernSecondaryButton' from 'src.toolbox.ui_kit.components' (c:\Users\wogud\OneDrive\Desktop\클로드코드\integrated_management_system\src\toolbox\ui_kit\components.py)
2025-08-18 21:26:56 - main - ERROR - 상세 오류: Traceback (most recent call last):
  File "c:\Users\wogud\OneDrive\Desktop\클로드코드\integrated_management_system\main.py", line 36, in load_features
    register_naver_cafe(app)
    ~~~~~~~~~~~~~~~~~~~^^^^^
  File "c:\Users\wogud\OneDrive\Desktop\클로드코드\integrated_management_system\src\features\naver_cafe\__init__.py", line 13, in register
    from .ui import NaverCafeWidget
  File "c:\Users\wogud\OneDrive\Desktop\클로드코드\integrated_management_system\src\features\naver_cafe\ui.py", line 13, in <module>
    from .control_widget import NaverCafeControlWidget
  File "c:\Users\wogud\OneDrive\Desktop\클로드코드\integrated_management_system\src\features\naver_cafe\control_widget.py", line 18, in <module>
    from src.toolbox.ui_kit.components import (
    ...<2 lines>...
    )
ImportError: cannot import name 'ModernSecondaryButton' from 'src.toolbox.ui_kit.components' (c:\Users\wogud\OneDrive\Desktop\클로드코드\integrated_management_system\src\toolbox\ui_kit\components.py)

2025-08-18 21:26:56 - desktop.app - ERROR - 애플리케이션 실행 실패: cannot import name 'ModernSecondaryButton' from 'src.toolbox.ui_kit.components' (c:\Users\wogud\OneDrive\Desktop\클로드코드\integrated_management_system\src\toolbox\ui_kit\components.py)
2025-08-18 21:26:56 - main - ERROR - 애플리케이션 시작 실패: cannot import name 'ModernSecondaryButton' from 'src.toolbox.ui_kit.components' (c:\Users\wogud\OneDrive\Desktop\클로드코드\integrated_management_system\src\toolbox\ui_kit\components.py)
2025-08-18 21:27:00 - main - ERROR - 기능 모듈 로드 실패: cannot import name 'ModernSecondaryButton' from 'src.toolbox.ui_kit.components' (c:\Users\wogud\OneDrive\Desktop\클로드코드\integrated_management_system\src\toolbox\ui_kit\components.py)
2025-08-18 21:27:00 - main - ERROR - 상세 오류: Traceback (most recent call last):
  File "c:\Users\wogud\OneDrive\Desktop\클로드코드\integrated_management_system\main.py", line 36, in load_features
    register_naver_cafe(app)
    ~~~~~~~~~~~~~~~~~~~^^^^^
  File "c:\Users\wogud\OneDrive\Desktop\클로드코드\integrated_management_system\src\features\naver_cafe\__init__.py", line 13, in register
    from .ui import NaverCafeWidget
  File "c:\Users\wogud\OneDrive\Desktop\클로드코드\integrated_management_system\src\features\naver_cafe\ui.py", line 13, in <module>
    from .control_widget import NaverCafeControlWidget
  File "c:\Users\wogud\OneDrive\Desktop\클로드코드\integrated_management_system\src\features\naver_cafe\control_widget.py", line 18, in <module>
    from src.toolbox.ui_kit.components import (
    ...<2 lines>...
    )
ImportError: cannot import name 'ModernSecondaryButton' from 'src.toolbox.ui_kit.components' (c:\Users\wogud\OneDrive\Desktop\클로드코드\integrated_management_system\src\toolbox\ui_kit\components.py)

2025-08-18 21:27:00 - desktop.app - ERROR - 애플리케이션 실행 실패: cannot import name 'ModernSecondaryButton' from 'src.toolbox.ui_kit.components' (c:\Users\wogud\OneDrive\Desktop\클로드코드\integrated_management_system\src\toolbox\ui_kit\components.py)
2025-08-18 21:27:00 - main - ERROR - 애플리케이션 시작 실패: cannot import name 'ModernSecondaryButton' from 'src.toolbox.ui_kit.components' (c:\Users\wogud\OneDrive\Desktop\클로드코드\integrated_management_system\src\toolbox\ui_kit\components.py)
2025-08-18 21:40:53 - main - ERROR - 기능 모듈 로드 실패: cannot import name 'ModernSecondaryButton' from 'src.toolbox.ui_kit.components' (c:\Users\wogud\OneDrive\Desktop\클로드코드\integrated_management_system\src\toolbox\ui_kit\components.py)
2025-08-18 21:40:53 - main - ERROR - 상세 오류: Traceback (most recent call last):
  File "c:\Users\wogud\OneDrive\Desktop\클로드코드\integrated_management_system\main.py", line 36, in load_features
    register_naver_cafe(app)
    ~~~~~~~~~~~~~~~~~~~^^^^^
  File "c:\Users\wogud\OneDrive\Desktop\클로드코드\integrated_management_system\src\features\naver_cafe\__init__.py", line 13, in register
    from .ui import NaverCafeWidget
  File "c:\Users\wogud\OneDrive\Desktop\클로드코드\integrated_management_system\src\features\naver_cafe\ui.py", line 13, in <module>
    from .control_widget import NaverCafeControlWidget
  File "c:\Users\wogud\OneDrive\Desktop\클로드코드\integrated_management_system\src\features\naver_cafe\control_widget.py", line 18, in <module>
    from src.toolbox.ui_kit.components import (
    ...<2 lines>...
    )
ImportError: cannot import name 'ModernSecondaryButton' from 'src.toolbox.ui_kit.components' (c:\Users\wogud\OneDrive\Desktop\클로드코드\integrated_management_system\src\toolbox\ui_kit\components.py)

2025-08-18 21:40:53 - desktop.app - ERROR - 애플리케이션 실행 실패: cannot import name 'ModernSecondaryButton' from 'src.toolbox.ui_kit.components' (c:\Users\wogud\OneDrive\Desktop\클로드코드\integrated_management_system\src\toolbox\ui_kit\components.py)
2025-08-18 21:40:53 - main - ERROR - 애플리케이션 시작 실패: cannot import name 'ModernSecondaryButton' from 'src.toolbox.ui_kit.components' (c:\Users\wogud\OneDrive\Desktop\클로드코드\integrated_management_system\src\toolbox\ui_kit\components.py)
2025-08-18 21:41:10 - main - ERROR - 기능 모듈 로드 실패: cannot import name 'ModernSecondaryButton' from 'src.toolbox.ui_kit.components' (c:\Users\wogud\OneDrive\Desktop\클로드코드\integrated_management_system\src\toolbox\ui_kit\components.py)
2025-08-18 21:41:10 - main - ERROR - 상세 오류: Traceback (most recent call last):
  File "c:\Users\wogud\OneDrive\Desktop\클로드코드\integrated_management_system\main.py", line 36, in load_features
    register_naver_cafe(app)
    ~~~~~~~~~~~~~~~~~~~^^^^^
  File "c:\Users\wogud\OneDrive\Desktop\클로드코드\integrated_management_system\src\features\naver_cafe\__init__.py", line 13, in register
    from .ui import NaverCafeWidget
  File "c:\Users\wogud\OneDrive\Desktop\클로드코드\integrated_management_system\src\features\naver_cafe\ui.py", line 13, in <module>
    from .control_widget import NaverCafeControlWidget
  File "c:\Users\wogud\OneDrive\Desktop\클로드코드\integrated_management_system\src\features\naver_cafe\control_widget.py", line 18, in <module>
    from src.toolbox.ui_kit.components import (
    ...<2 lines>...
    )
ImportError: cannot import name 'ModernSecondaryButton' from 'src.toolbox.ui_kit.components' (c:\Users\wogud\OneDrive\Desktop\클로드코드\integrated_management_system\src\toolbox\ui_kit\components.py)

2025-08-18 21:41:10 - desktop.app - ERROR - 애플리케이션 실행 실패: cannot import name 'ModernSecondaryButton' from 'src.toolbox.ui_kit.components' (c:\Users\wogud\OneDrive\Desktop\클로드코드\integrated_management_system\src\toolbox\ui_kit\components.py)
2025-08-18 21:41:10 - main - ERROR - 애플리케이션 시작 실패: cannot import name 'ModernSecondaryButton' from 'src.toolbox.ui_kit.components' (c:\Users\wogud\OneDrive\Desktop\클로드코드\integrated_management_system\src\toolbox\ui_kit\components.py)
2025-08-18 21:42:51 - main - ERROR - 기능 모듈 로드 실패: No module named 'src.features.naver_cafe.config'
2025-08-18 21:42:51 - main - ERROR - 상세 오류: Traceback (most recent call last):
  File "C:\Users\wogud\OneDrive\Desktop\클로드코드\integrated_management_system\main.py", line 36, in load_features
    register_naver_cafe(app)
    ~~~~~~~~~~~~~~~~~~~^^^^^
  File "C:\Users\wogud\OneDrive\Desktop\클로드코드\integrated_management_system\src\features\naver_cafe\__init__.py", line 13, in register
    from .ui import NaverCafeWidget
  File "C:\Users\wogud\OneDrive\Desktop\클로드코드\integrated_management_system\src\features\naver_cafe\ui.py", line 13, in <module>
    from .control_widget import NaverCafeControlWidget
  File "C:\Users\wogud\OneDrive\Desktop\클로드코드\integrated_management_system\src\features\naver_cafe\control_widget.py", line 25, in <module>
    from .worker import NaverCafeUnifiedWorker
  File "C:\Users\wogud\OneDrive\Desktop\클로드코드\integrated_management_system\src\features\naver_cafe\worker.py", line 17, in <module>
    from .config import CAFE_EXTRACTION_CONFIG
ModuleNotFoundError: No module named 'src.features.naver_cafe.config'

2025-08-18 21:42:51 - desktop.app - ERROR - 애플리케이션 실행 실패: No module named 'src.features.naver_cafe.config'
2025-08-18 21:42:51 - main - ERROR - 애플리케이션 시작 실패: No module named 'src.features.naver_cafe.config'
2025-08-18 21:43:08 - main - ERROR - 기능 모듈 로드 실패: No module named 'src.features.naver_cafe.config'
2025-08-18 21:43:08 - main - ERROR - 상세 오류: Traceback (most recent call last):
  File "C:\Users\wogud\OneDrive\Desktop\클로드코드\integrated_management_system\main.py", line 36, in load_features
    register_naver_cafe(app)
    ~~~~~~~~~~~~~~~~~~~^^^^^
  File "C:\Users\wogud\OneDrive\Desktop\클로드코드\integrated_management_system\src\features\naver_cafe\__init__.py", line 13, in register
    from .ui import NaverCafeWidget
  File "C:\Users\wogud\OneDrive\Desktop\클로드코드\integrated_management_system\src\features\naver_cafe\ui.py", line 13, in <module>
    from .control_widget import NaverCafeControlWidget
  File "C:\Users\wogud\OneDrive\Desktop\클로드코드\integrated_management_system\src\features\naver_cafe\control_widget.py", line 27, in <module>
    from .config import CAFE_EXTRACTION_CONFIG, ERROR_MESSAGES, SUCCESS_MESSAGES
ModuleNotFoundError: No module named 'src.features.naver_cafe.config'

2025-08-18 21:43:08 - desktop.app - ERROR - 애플리케이션 실행 실패: No module named 'src.features.naver_cafe.config'
2025-08-18 21:43:08 - main - ERROR - 애플리케이션 시작 실패: No module named 'src.features.naver_cafe.config'
2025-08-18 21:43:22 - main - ERROR - 기능 모듈 로드 실패: name 'CAFE_EXTRACTION_CONFIG' is not defined
2025-08-18 21:43:22 - main - ERROR - 상세 오류: Traceback (most recent call last):
  File "C:\Users\wogud\OneDrive\Desktop\클로드코드\integrated_management_system\main.py", line 36, in load_features
    register_naver_cafe(app)
    ~~~~~~~~~~~~~~~~~~~^^^^^
  File "C:\Users\wogud\OneDrive\Desktop\클로드코드\integrated_management_system\src\features\naver_cafe\__init__.py", line 15, in register
    widget = NaverCafeWidget()
  File "C:\Users\wogud\OneDrive\Desktop\클로드코드\integrated_management_system\src\features\naver_cafe\ui.py", line 22, in __init__
    self.setup_ui()
    ~~~~~~~~~~~~~^^
  File "C:\Users\wogud\OneDrive\Desktop\클로드코드\integrated_management_system\src\features\naver_cafe\ui.py", line 46, in setup_ui
    self.control_widget = NaverCafeControlWidget()
                          ~~~~~~~~~~~~~~~~~~~~~~^^
  File "C:\Users\wogud\OneDrive\Desktop\클로드코드\integrated_management_system\src\features\naver_cafe\control_widget.py", line 58, in __init__
    self.max_search_retries = CAFE_EXTRACTION_CONFIG["max_retry_count"]
                              ^^^^^^^^^^^^^^^^^^^^^^
NameError: name 'CAFE_EXTRACTION_CONFIG' is not defined

2025-08-18 21:43:22 - desktop.app - ERROR - 애플리케이션 실행 실패: name 'CAFE_EXTRACTION_CONFIG' is not defined
2025-08-18 21:43:22 - main - ERROR - 애플리케이션 시작 실패: name 'CAFE_EXTRACTION_CONFIG' is not defined
2025-08-18 21:43:48 - main - ERROR - 기능 모듈 로드 실패: name 'CAFE_EXTRACTION_CONFIG' is not defined
2025-08-18 21:43:48 - main - ERROR - 상세 오류: Traceback (most recent call last):
  File "C:\Users\wogud\OneDrive\Desktop\클로드코드\integrated_management_system\main.py", line 36, in load_features
    register_naver_cafe(app)
    ~~~~~~~~~~~~~~~~~~~^^^^^
  File "C:\Users\wogud\OneDrive\Desktop\클로드코드\integrated_management_system\src\features\naver_cafe\__init__.py", line 15, in register
    widget = NaverCafeWidget()
  File "C:\Users\wogud\OneDrive\Desktop\클로드코드\integrated_management_system\src\features\naver_cafe\ui.py", line 22, in __init__
    self.setup_ui()
    ~~~~~~~~~~~~~^^
  File "C:\Users\wogud\OneDrive\Desktop\클로드코드\integrated_management_system\src\features\naver_cafe\ui.py", line 46, in setup_ui
    self.control_widget = NaverCafeControlWidget()
                          ~~~~~~~~~~~~~~~~~~~~~~^^
  File "C:\Users\wogud\OneDrive\Desktop\클로드코드\integrated_management_system\src\features\naver_cafe\control_widget.py", line 70, in __init__
    self.setup_ui()
    ~~~~~~~~~~~~~^^
  File "C:\Users\wogud\OneDrive\Desktop\클로드코드\integrated_management_system\src\features\naver_cafe\control_widget.py", line 98, in setup_ui
    settings_card = self.create_settings_card()
  File "C:\Users\wogud\OneDrive\Desktop\클로드코드\integrated_management_system\src\features\naver_cafe\control_widget.py", line 455, in create_settings_card
    self.start_page_spin.setValue(CAFE_EXTRACTION_CONFIG["default_page_range"]["start"])
                                  ^^^^^^^^^^^^^^^^^^^^^^
NameError: name 'CAFE_EXTRACTION_CONFIG' is not defined

2025-08-18 21:43:48 - desktop.app - ERROR - 애플리케이션 실행 실패: name 'CAFE_EXTRACTION_CONFIG' is not defined
2025-08-18 21:43:48 - main - ERROR - 애플리케이션 시작 실패: name 'CAFE_EXTRACTION_CONFIG' is not defined
2025-08-18 21:44:17 - main - ERROR - 기능 모듈 로드 실패: name 'ModernButton' is not defined
2025-08-18 21:44:17 - main - ERROR - 상세 오류: Traceback (most recent call last):
  File "C:\Users\wogud\OneDrive\Desktop\클로드코드\integrated_management_system\main.py", line 36, in load_features
    register_naver_cafe(app)
    ~~~~~~~~~~~~~~~~~~~^^^^^
  File "C:\Users\wogud\OneDrive\Desktop\클로드코드\integrated_management_system\src\features\naver_cafe\__init__.py", line 15, in register
    widget = NaverCafeWidget()
  File "C:\Users\wogud\OneDrive\Desktop\클로드코드\integrated_management_system\src\features\naver_cafe\ui.py", line 22, in __init__
    self.setup_ui()
    ~~~~~~~~~~~~~^^
  File "C:\Users\wogud\OneDrive\Desktop\클로드코드\integrated_management_system\src\features\naver_cafe\ui.py", line 49, in setup_ui
    self.results_widget = NaverCafeResultsWidget()
                          ~~~~~~~~~~~~~~~~~~~~~~^^
  File "C:\Users\wogud\OneDrive\Desktop\클로드코드\integrated_management_system\src\features\naver_cafe\results_widget.py", line 33, in __init__
    self.setup_ui()
    ~~~~~~~~~~~~~^^
  File "C:\Users\wogud\OneDrive\Desktop\클로드코드\integrated_management_system\src\features\naver_cafe\results_widget.py", line 72, in setup_ui
    users_tab = self.create_users_tab()
  File "C:\Users\wogud\OneDrive\Desktop\클로드코드\integrated_management_system\src\features\naver_cafe\results_widget.py", line 166, in create_users_tab
    self.copy_button = ModernButton("📋 복사", "secondary")
                       ^^^^^^^^^^^^
NameError: name 'ModernButton' is not defined

2025-08-18 21:44:17 - desktop.app - ERROR - 애플리케이션 실행 실패: name 'ModernButton' is not defined
2025-08-18 21:44:17 - main - ERROR - 애플리케이션 시작 실패: name 'ModernButton' is not defined
2025-08-18 22:01:16 - main - ERROR - 기능 모듈 로드 실패: name 'layout' is not defined
2025-08-18 22:01:16 - main - ERROR - 상세 오류: Traceback (most recent call last):
  File "c:\Users\wogud\OneDrive\Desktop\클로드코드\integrated_management_system\main.py", line 36, in load_features
    register_naver_cafe(app)
    ~~~~~~~~~~~~~~~~~~~^^^^^
  File "c:\Users\wogud\OneDrive\Desktop\클로드코드\integrated_management_system\src\features\naver_cafe\__init__.py", line 15, in register
    widget = NaverCafeWidget()
  File "c:\Users\wogud\OneDrive\Desktop\클로드코드\integrated_management_system\src\features\naver_cafe\ui.py", line 22, in __init__
    self.setup_ui()
    ~~~~~~~~~~~~~^^
  File "c:\Users\wogud\OneDrive\Desktop\클로드코드\integrated_management_system\src\features\naver_cafe\ui.py", line 46, in setup_ui
    self.control_widget = NaverCafeControlWidget()
                          ~~~~~~~~~~~~~~~~~~~~~~^^
  File "c:\Users\wogud\OneDrive\Desktop\클로드코드\integrated_management_system\src\features\naver_cafe\control_widget.py", line 64, in __init__
    self.setup_ui()
    ~~~~~~~~~~~~~^^
  File "c:\Users\wogud\OneDrive\Desktop\클로드코드\integrated_management_system\src\features\naver_cafe\control_widget.py", line 84, in setup_ui
    cafe_card = self.create_cafe_card()
  File "c:\Users\wogud\OneDrive\Desktop\클로드코드\integrated_management_system\src\features\naver_cafe\control_widget.py", line 316, in create_cafe_card
    layout.addWidget(self.cafe_combo)
    ^^^^^^
NameError: name 'layout' is not defined. Did you mean: 'self.layout'?

2025-08-18 22:01:16 - desktop.app - ERROR - 애플리케이션 실행 실패: name 'layout' is not defined
2025-08-18 22:01:16 - main - ERROR - 애플리케이션 시작 실패: name 'layout' is not defined
2025-08-18 22:01:19 - main - ERROR - 기능 모듈 로드 실패: name 'layout' is not defined
2025-08-18 22:01:19 - main - ERROR - 상세 오류: Traceback (most recent call last):
  File "c:\Users\wogud\OneDrive\Desktop\클로드코드\integrated_management_system\main.py", line 36, in load_features
    register_naver_cafe(app)
    ~~~~~~~~~~~~~~~~~~~^^^^^
  File "c:\Users\wogud\OneDrive\Desktop\클로드코드\integrated_management_system\src\features\naver_cafe\__init__.py", line 15, in register
    widget = NaverCafeWidget()
  File "c:\Users\wogud\OneDrive\Desktop\클로드코드\integrated_management_system\src\features\naver_cafe\ui.py", line 22, in __init__
    self.setup_ui()
    ~~~~~~~~~~~~~^^
  File "c:\Users\wogud\OneDrive\Desktop\클로드코드\integrated_management_system\src\features\naver_cafe\ui.py", line 46, in setup_ui
    self.control_widget = NaverCafeControlWidget()
                          ~~~~~~~~~~~~~~~~~~~~~~^^
  File "c:\Users\wogud\OneDrive\Desktop\클로드코드\integrated_management_system\src\features\naver_cafe\control_widget.py", line 64, in __init__
    self.setup_ui()
    ~~~~~~~~~~~~~^^
  File "c:\Users\wogud\OneDrive\Desktop\클로드코드\integrated_management_system\src\features\naver_cafe\control_widget.py", line 84, in setup_ui
    cafe_card = self.create_cafe_card()
  File "c:\Users\wogud\OneDrive\Desktop\클로드코드\integrated_management_system\src\features\naver_cafe\control_widget.py", line 316, in create_cafe_card
    layout.addWidget(self.cafe_combo)
    ^^^^^^
NameError: name 'layout' is not defined. Did you mean: 'self.layout'?

2025-08-18 22:01:19 - desktop.app - ERROR - 애플리케이션 실행 실패: name 'layout' is not defined
2025-08-18 22:01:19 - main - ERROR - 애플리케이션 시작 실패: name 'layout' is not defined
2025-08-18 22:01:33 - main - ERROR - 기능 모듈 로드 실패: name 'layout' is not defined
2025-08-18 22:01:33 - main - ERROR - 상세 오류: Traceback (most recent call last):
  File "c:\Users\wogud\OneDrive\Desktop\클로드코드\integrated_management_system\main.py", line 36, in load_features
    register_naver_cafe(app)
    ~~~~~~~~~~~~~~~~~~~^^^^^
  File "c:\Users\wogud\OneDrive\Desktop\클로드코드\integrated_management_system\src\features\naver_cafe\__init__.py", line 15, in register
    widget = NaverCafeWidget()
  File "c:\Users\wogud\OneDrive\Desktop\클로드코드\integrated_management_system\src\features\naver_cafe\ui.py", line 22, in __init__
    self.setup_ui()
    ~~~~~~~~~~~~~^^
  File "c:\Users\wogud\OneDrive\Desktop\클로드코드\integrated_management_system\src\features\naver_cafe\ui.py", line 46, in setup_ui
    self.control_widget = NaverCafeControlWidget()
                          ~~~~~~~~~~~~~~~~~~~~~~^^
  File "c:\Users\wogud\OneDrive\Desktop\클로드코드\integrated_management_system\src\features\naver_cafe\control_widget.py", line 64, in __init__
    self.setup_ui()
    ~~~~~~~~~~~~~^^
  File "c:\Users\wogud\OneDrive\Desktop\클로드코드\integrated_management_system\src\features\naver_cafe\control_widget.py", line 88, in setup_ui
    board_card = self.create_board_card()
  File "c:\Users\wogud\OneDrive\Desktop\클로드코드\integrated_management_system\src\features\naver_cafe\control_widget.py", line 427, in create_board_card
    layout.addWidget(self.board_combo)
    ^^^^^^
NameError: name 'layout' is not defined. Did you mean: 'self.layout'?

2025-08-18 22:01:33 - desktop.app - ERROR - 애플리케이션 실행 실패: name 'layout' is not defined
2025-08-18 22:01:33 - main - ERROR - 애플리케이션 시작 실패: name 'layout' is not defined
2025-08-18 22:18:04 - features.naver_cafe.adapters - ERROR - Meta CSV 파일 저장 실패: [Errno 13] Permission denied: 'C:/Users/wogud/Downloads/네이버카페_Meta_20250818_2217.csv'
